Workbook

Sheet WBS
A1: 인공지능&빅데이터 서비스 기반 홈트레이닝 구독 서비스 | W1: 계획진도율 | X1: =W5 -> 0.705
W2: 전체진행률 | X2: =X5 -> 0.51458333 | Z2: 1주차 | AH2: 2주차 | AO2: 3주차 | AV2: 4주차 | BC2: 5주차 | BJ2: 6주차
Z3: 45973 | AA3: 45974 | AB3: 45975 | AC3: 45976 | AD3: 45977 | AE3: 45978 | AF3: 45979 | AG3: 45980 | AH3: 45981 | AI3: 45982 | AJ3: 45983 | AK3: 45984 | AL3: 45985 | AM3: 45986 | AN3: 45987 | AO3: 45988 | AP3: 45989 | AQ3: 45990 | AR3: 45991 | AS3: 45992 | AT3: 45993 | AU3: 45994 | AV3: 45995 | AW3: 45996 | AX3: 45997 | AY3: 45998 | AZ3: 45999 | BA3: 46000 | BB3: 46001 | BC3: 46002 | BD3: 46003 | BE3: 46004 | BF3: 46005 | BG3: 46006 | BH3: 46007 | BI3: 46008 | BJ3: 46009 | BK3: 46010 | BL3: 46011 | BM3: 46012 | BN3: 46013 | BO3: 46014 | BP3: 46015
A4: WBS | B4: 태스크 | C4: 도입기업 담당자 | D4: 공급기업 담당자 | E4: 상태 | F4: 계획 시작일 | G4: 계획 종료일 | H4: 기간 | K4: 자원(MM) | L4: 예산(만원) | M4: 우선순위 | N4: 기간 | O4: 투입계획M/D | P4: 투입실적M/D | Q4: 방문근무M/D | R4: 도입기업방문자 | S4: 산출물 | T4: 실제 시작일 | U4: 실제 종료일 | V4: 가중치 (100%) | W4: 계획 진도율 | X4: 실제 진척도 | Z4: 작업일정계획
A5: 1 | B5: 전체 프로젝트 | D5: - | E5: =IF(AND(X5>0%,X5<100%),"진행 중",IF(X5=0%,"작업 대기","작업 완료")) -> 진행 중 | F5: 45973 | G5: 45975 | H5: =NETWORKDAYS(F5,G5) -> 3 | I5: =G5-F5 -> 2 | J5: =F5+(INT(I5*X5)) -> 45974 | K5: =SUM(#REF!,K7,K16) -> #REF! | L5: =VLOOKUP(A5,Prj_list!$A$5:$K$59,10,FALSE)/10000 -> 300 | M5: =VLOOKUP(A5,Prj_list!$A$5:$I$59,9,FALSE) -> 2 | N5: =G5-F5 -> 2 | O5: =SUM(O68,O63,O19,O12,O6) -> 214 | W5: =W6+W12+W19+W63+W68 -> 0.705 | X5: =X6+X12+X19+X63+X68 -> 0.51458333
A6: 1.1 | B6: 분석단계(AD) | E6: 진행 중 | F6: =IF(MIN(F7:F10)=0,"",MIN(F7:F10)) -> 45973 | G6: =IF(MAX(G7:G10)=0,"",MAX(G7:G10)) -> 45980 | H6: =NETWORKDAYS(F6,G6) -> 6 | I6: =G6-F6 -> 7 | J6: =IF(X6=0,F6-1,F6+(INT(I6*X6))) -> 45973 | N6: =G6-F6 -> 7 | O6: =SUM(O7:O10) -> 0 | S6: 업무 분석 및 설계 | T6: =IF(MIN(T7:T10)=0,"",MIN(T7:T10)) -> 45973 | U6: 45974 | V6: 0.15 | W6: =AVERAGE(W7:W10)*V6 -> 0.135 | X6: =AVERAGE(X7:X10)*V6 -> 0.12375
A7: 1.1.1 | B7: 프로젝트 범위 정의 | C7: TFT | E7: =IF(AND(X7>0%,X7<100%),"진행 중",IF(X7=0%,"작업 대기","작업 완료")) -> 작업 완료 | F7: 45973 | G7: 45974 | H7: =NETWORKDAYS(F7,G7) -> 2 | I7: =G7-F7 -> 1 | J7: =IF(X7=0,F7-1,F7+(INT(I7*X7))) -> 45974 | N7: =(G7-F7)+1 -> 2 | O7: 0 | S7: 고객요구사항 명세서 | T7: 45973 | U7: 45974 | W7: 1 | X7: 1
A8: 1.1.2 | B8: 주요 기능 및 아이디어 정리 | C8: TFT | E8: =IF(AND(X8>0%,X8<100%),"진행 중",IF(X8=0%,"작업 대기","작업 완료")) -> 작업 완료 | F8: 45974 | G8: 45975 | H8: =NETWORKDAYS(F8,G8) -> 2 | I8: =G8-F8 -> 1 | J8: =IF(X8=0,F8-1,F8+(INT(I8*X8))) -> 45975 | N8: =(G8-F8)+1 -> 2 | O8: 0 | S8: 고객요구사항 명세서 | T8: 45974 | U8: 45975 | W8: 1 | X8: 1
A9: 1.1.3 | B9: 요구사항 정의 | C9: PM,TFT | E9: =IF(AND(X9>0%,X9<100%),"진행 중",IF(X9=0%,"작업 대기","작업 완료")) -> 진행 중 | F9: 45978 | G9: 45979 | H9: =NETWORKDAYS(F9,G9) -> 2 | I9: =G9-F9 -> 1 | J9: =IF(X9=0,F9-1,F9+(INT(I9*X9))) -> 45978 | N9: =(G9-F9)+1 -> 2 | O9: 0 | S9: 개선 업무 절차 흐름도 | T9: 45978 | U9: 45979 | W9: 0.8 | X9: 0.8
A10: 1.1.4 | B10: 데이터 수집 계획 수립 | C10: PM,TFT | E10: =IF(AND(X10>0%,X10<100%),"진행 중",IF(X10=0%,"작업 대기","작업 완료")) -> 진행 중 | F10: 45978 | G10: 45980 | H10: =NETWORKDAYS(F10,G10) -> 3 | I10: =G10-F10 -> 2 | J10: =IF(X10=0,F10-1,F10+(INT(I10*X10))) -> 45979 | N10: =(G10-F10)+1 -> 3 | O10: 0 | S10: 개선 업무 절차 흐름도 | T10: 45978 | W10: 0.8 | X10: 0.5
A12: 1.2 | B12: 설계(TD) | E12: =IF(AND(X12>0%,X12<100%),"진행 중",IF(X12=0%,"작업 대기","작업 완료")) -> 진행 중 | F12: =IF(MIN(F13:F18)=0,"",MIN(F13:F18)) -> 45981 | G12: =IF(MAX(G13:G18)=0,"",MAX(G13:G18)) -> 45984 | H12: =NETWORKDAYS(F12,G12) -> 2 | I12: =G12-F12 -> 3 | J12: =IF(X12=0,F12-1,F12+(INT(I12*X12))) -> 45981 | N12: =G12-F12 -> 3 | O12: =SUM(O13:O15) -> 9 | S12: 기술설계 | T12: =IF(MIN(T13:T18)=0,"",MIN(T13:T18)) -> 45979 | U12: =IF(MAX(U13:U18)=0,"",MAX(U13:U18)) -> 45987 | V12: 0.25 | W12: =AVERAGE(W13:W18)*V12 -> 0.22 | X12: =AVERAGE(X13:X18)*V12 -> 0.12
A13: 1.2.1 | B13: 메뉴정의 | C13: TFT | E13: =IF(AND(X13>0%,X13<100%),"진행 중",IF(X13=0%,"작업 대기","작업 완료")) -> 진행 중 | F13: 45981 | G13: 45984 | H13: =NETWORKDAYS(F13,G13) -> 2 | I13: =G13-F13 -> 3 | J13: =IF(X13=0,F13-1,F13+(INT(I13*X13))) -> 45983 | N13: =(G13-F13)+1 -> 4 | O13: 2 | S13: 프로그램 일람표 | T13: 45979 | U13: 45979 | W13: 0.8 | X13: 0.8
A14: 1.2.2 | B14: 화면설계 | C14: 강혁 | E14: =IF(AND(X14>0%,X14<100%),"진행 중",IF(X14=0%,"작업 대기","작업 완료")) -> 진행 중 | F14: 45981 | G14: 45984 | H14: =NETWORKDAYS(F14,G14) -> 2 | I14: =G14-F14 -> 3 | N14: =(G14-F14)+1 -> 4 | O14: 3 | S14: 화면목록 및 명세서 | T14: 45987 | U14: 45987 | W14: 0.8 | X14: 0.8
A15: 1.2.3 | B15: DataBase 설계(래) | C15: 강혁 | E15: =IF(AND(X15>0%,X15<100%),"진행 중",IF(X15=0%,"작업 대기","작업 완료")) -> 진행 중 | F15: 45981 | G15: 45984 | H15: =NETWORKDAYS(F15,G15) -> 2 | I15: =G15-F15 -> 3 | J15: =IF(X15=0,F15-1,F15+(INT(I15*X15))) -> 45983 | N15: =(G15-F15)+1 -> 4 | O15: 4 | S15: Table layout 정의서 | T15: 45979 | U15: 45981 | W15: 0.8 | X15: 0.8
W17: 1 | X17: 0
W18: 1 | X18: 0
A19: 1.3 | B19: 코딩(CD) | E19: =IF(AND(X19>0%,X19<100%),"진행 중",IF(X19=0%,"작업 대기","작업 완료")) -> 진행 중 | F19: =IF(MIN(F20:F62)=0,"",MIN(F20:F62)) -> 45980 | G19: =IF(MAX(G20:G62)=0,"",MAX(G20:G62)) -> 46008 | H19: =NETWORKDAYS(F19,G19) -> 21 | I19: =G19-F19 -> 28 | J19: =IF(X19=0,F19-1,F19+(INT(I19*X19))) -> 45987 | N19: =G19-F19 -> 28 | O19: =SUM(O20:O61) -> 160 | S19: 개발 | V19: 0.35 | W19: =AVERAGE(W20:W62)*V19 -> 0.35 | X19: =AVERAGE(X20:X62)*V19 -> 0.27083333
A20: 1.3.1 | B20: 회원기능 - 계정생성(비) | E20: =IF(AND(X20>0%,X20<100%),"진행 중",IF(X20=0%,"작업 대기","작업 완료")) -> 작업 완료 | F20: 45980 | G20: 45981 | H20: =NETWORKDAYS(F20,G20) -> 2 | I20: =G20-F20 -> 1 | J20: =IF(X20=0,F20-1,F20+(INT(I20*X20))) -> 45981 | N20: =(G20-F20)+1 -> 2 | O20: 2 | S20: 프로그램 Source | T20: 45980 | U20: 45981 | W20: 1 | X20: 1
B21: 회원기능 - 계정생성(현) | E21: =IF(AND(X21>0%,X21<100%),"진행 중",IF(X21=0%,"작업 대기","작업 완료")) -> 작업 완료 | F21: 45980 | G21: 45981 | H21: =NETWORKDAYS(F21,G21) -> 2 | I21: =G21-F21 -> 1 | J21: =IF(X21=0,F21-1,F21+(INT(I21*X21))) -> 45981 | N21: =(G21-F21)+1 -> 2 | T21: 45980 | U21: 45989 | W21: 1 | X21: 1
A22: 1.3.2 | B22: 회원기능 - 로그인(비) | E22: =IF(AND(X22>0%,X22<100%),"진행 중",IF(X22=0%,"작업 대기","작업 완료")) -> 작업 완료 | F22: 45981 | G22: 45982 | H22: =NETWORKDAYS(F22,G22) -> 2 | I22: =G22-F22 -> 1 | J22: =IF(X22=0,F22-1,F22+(INT(I22*X22))) -> 45982 | N22: =(G22-F22)+1 -> 2 | O22: 39 | S22: 프로그램 Source | T22: 45980 | U22: 45981 | W22: 1 | X22: 1
B23: 회원기능 - 로그인(현) | E23: =IF(AND(X23>0%,X23<100%),"진행 중",IF(X23=0%,"작업 대기","작업 완료")) -> 작업 완료 | F23: 45981 | G23: 45982 | H23: =NETWORKDAYS(F23,G23) -> 2 | I23: =G23-F23 -> 1 | J23: =IF(X23=0,F23-1,F23+(INT(I23*X23))) -> 45982 | N23: =(G23-F23)+1 -> 2 | T23: 45989 | U23: 45989 | W23: 1 | X23: 1
A24: 1.3.3 | B24: 회원기능 - 로그아웃(비) | E24: =IF(AND(X24>0%,X24<100%),"진행 중",IF(X24=0%,"작업 대기","작업 완료")) -> 작업 완료 | F24: 45985 | G24: 45986 | H24: =NETWORKDAYS(F24,G24) -> 2 | I24: =G24-F24 -> 1 | J24: =IF(X24=0,F24-1,F24+(INT(I24*X24))) -> 45986 | N24: =(G24-F24)+1 -> 2 | O24: 39 | S24: 프로그램 Source | T24: 45980 | U24: 45981 | W24: 1 | X24: 1
B25: 회원기능 - 로그아웃(현) | E25: =IF(AND(X25>0%,X25<100%),"진행 중",IF(X25=0%,"작업 대기","작업 완료")) -> 작업 완료 | F25: 45985 | G25: 45986 | H25: =NETWORKDAYS(F25,G25) -> 2 | I25: =G25-F25 -> 1 | J25: =IF(X25=0,F25-1,F25+(INT(I25*X25))) -> 45986 | N25: =(G25-F25)+1 -> 2 | T25: 45989 | U25: 45989 | W25: 1 | X25: 1
A26: 1.3.4 | B26: 회원기능 - 비밀번호 재설정/탈퇴(비) | E26: =IF(AND(X26>0%,X26<100%),"진행 중",IF(X26=0%,"작업 대기","작업 완료")) -> 작업 완료 | F26: 45992 | G26: 45993 | H26: =NETWORKDAYS(F26,G26) -> 2 | I26: =G26-F26 -> 1 | J26: =IF(X26=0,F26-1,F26+(INT(I26*X26))) -> 45993 | N26: =(G26-F26)+1 -> 2 | O26: 20 | S26: 프로그램 Source | T26: 45980 | U26: 45981 | W26: 1 | X26: 1
B27: 회원기능 - 비밀번호 재설정/탈퇴(현) | E27: =IF(AND(X27>0%,X27<100%),"진행 중",IF(X27=0%,"작업 대기","작업 완료")) -> 작업 완료 | F27: 45992 | G27: 45993 | H27: =NETWORKDAYS(F27,G27) -> 2 | I27: =G27-F27 -> 1 | J27: =IF(X27=0,F27-1,F27+(INT(I27*X27))) -> 45993 | N27: =(G27-F27)+1 -> 2 | T27: 45989 | U27: 45989 | W27: 1 | X27: 1
A28: 1.3.5 | B28: 회원기능 - 개인정보 관리(비) | E28: =IF(AND(X28>0%,X28<100%),"진행 중",IF(X28=0%,"작업 대기","작업 완료")) -> 작업 완료 | F28: 45993 | G28: 45994 | H28: =NETWORKDAYS(F28,G28) -> 2 | I28: =G28-F28 -> 1 | J28: =IF(X28=0,F28-1,F28+(INT(I28*X28))) -> 45994 | N28: =(G28-F28)+1 -> 2 | O28: 10 | S28: 프로그램 Source | T28: 45980 | U28: 45981 | W28: 1 | X28: 1
B29: 회원기능 - 개인정보 관리(비) | E29: =IF(AND(X29>0%,X29<100%),"진행 중",IF(X29=0%,"작업 대기","작업 완료")) -> 작업 완료 | F29: 45993 | G29: 45994 | H29: =NETWORKDAYS(F29,G29) -> 2 | I29: =G29-F29 -> 1 | J29: =IF(X29=0,F29-1,F29+(INT(I29*X29))) -> 45994 | N29: =(G29-F29)+1 -> 2 | T29: 45992 | U29: 45994 | W29: 1 | X29: 1
A30: 1.3.6 | B30: 회원기능 - 게시글 관리(비) | E30: =IF(AND(X30>0%,X30<100%),"진행 중",IF(X30=0%,"작업 대기","작업 완료")) -> 작업 완료 | F30: 45994 | G30: 45995 | H30: =NETWORKDAYS(F30,G30) -> 2 | I30: =G30-F30 -> 1 | J30: =IF(X30=0,F30-1,F30+(INT(I30*X30))) -> 45995 | N30: =(G30-F30)+1 -> 2 | O30: 10 | S30: 프로그램 Source | T30: 45982 | U30: 45982 | W30: 1 | X30: 1
B31: 회원기능 - 게시글 관리(비) | E31: =IF(AND(X31>0%,X31<100%),"진행 중",IF(X31=0%,"작업 대기","작업 완료")) -> 작업 완료 | F31: 45994 | G31: 45995 | H31: =NETWORKDAYS(F31,G31) -> 2 | I31: =G31-F31 -> 1 | J31: =IF(X31=0,F31-1,F31+(INT(I31*X31))) -> 45995 | N31: =(G31-F31)+1 -> 2 | T31: 45992 | U31: 45994 | W31: 1 | X31: 1
A32: 1.3.7 | B32: 구독기능 - 구독 서비스 관리(현) | E32: =IF(AND(X32>0%,X32<100%),"진행 중",IF(X32=0%,"작업 대기","작업 완료")) -> 작업 대기 | F32: 45986 | G32: 45987 | N32: =(G32-F32)+1 -> 2 | W32: 1 | X32: 0
A33: 1.3.8 | B33: 구독기능 - 관절 가동범위 관리(현) | E33: =IF(AND(X33>0%,X33<100%),"진행 중",IF(X33=0%,"작업 대기","작업 완료")) -> 작업 대기 | F33: 45987 | G33: 45988 | N33: =(G33-F33)+1 -> 2 | W33: 1 | X33: 0
A34: 1.3.9 | B34: 구독기능 - 관절 가동범위 조회(현) | E34: =IF(AND(X34>0%,X34<100%),"진행 중",IF(X34=0%,"작업 대기","작업 완료")) -> 작업 대기 | F34: 45988 | G34: 45989 | N34: =(G34-F34)+1 -> 2 | W34: 1 | X34: 0
A35: 1.3.10 | B35: 신체정보 - 신체정보 관리(래) | E35: 작업 완료 | F35: 45987 | G35: 45989 | N35: =(G35-F35)+1 -> 3 | T35: 45987 | U35: 45995 | W35: 1 | X35: 1
A36: 1.3.11 | B36: 신체정보 - 신체정보 자동 갱신(래) | E36: 작업 완료 | F36: 45992 | G36: 45993 | N36: =(G36-F36)+1 -> 2 | T36: 45987 | U36: 45995 | W36: 1 | X36: 1
A37: 1.3.12 | B37: 신체정보 - 신체정보 이력 관리(래) | E37: 진행중 | F37: 45994 | G37: 45995 | N37: =(G37-F37)+1 -> 2 | T37: 45987 | W37: 1 | X37: 0.7
A38: 1.3.13 | B38: 맞춤형기능 - 개인 상세 정보 기입 | E38: 작업 대기 | F38: 45996 | G38: 45998 | N38: =(G38-F38)+1 -> 3 | W38: 1 | X38: 0
A39: 1.3.14 | B39: 맞춤형기능 - 체력 측정 기능 | E39: =IF(AND(X39>0%,X39<100%),"진행 중",IF(X39=0%,"작업 대기","작업 완료")) -> 작업 대기 | F39: 45999 | G39: 46002 | N39: =(G39-F39)+1 -> 4 | W39: 1 | X39: 0
A40: 1.3.15 | B40: 맞춤형기능 - 기간별 루틴 제공 | E40: =IF(AND(X40>0%,X40<100%),"진행 중",IF(X40=0%,"작업 대기","작업 완료")) -> 작업 완료 | F40: 45992 | G40: 45993 | H40: =NETWORKDAYS(F40,G40) -> 2 | I40: =G40-F40 -> 1 | J40: =IF(X40=0,F40-1,F40+(INT(I40*X40))) -> 45993 | N40: =(G40-F40)+1 -> 2 | O40: 10 | S40: 프로그램 Source | T40: 45989 | U40: 45994 | W40: 1 | X40: 1
A41: 1.3.16 | B41: 맞춤형기능 - 기간별 식단 제공 | E41: =IF(AND(X41>0%,X41<100%),"진행 중",IF(X41=0%,"작업 대기","작업 완료")) -> 작업 완료 | F41: 45993 | G41: 45994 | H41: =NETWORKDAYS(F41,G41) -> 2 | I41: =G41-F41 -> 1 | J41: =IF(X41=0,F41-1,F41+(INT(I41*X41))) -> 45994 | N41: =(G41-F41)+1 -> 2 | O41: 10 | S41: 프로그램 Source | T41: 45989 | U41: 45994 | W41: 1 | X41: 1
A42: 1.3.17 | B42: 맞춤형기능 - 개인 레포트 기능 | E42: =IF(AND(X42>0%,X42<100%),"진행 중",IF(X42=0%,"작업 대기","작업 완료")) -> 작업 대기 | F42: 45994 | G42: 45995 | H42: =NETWORKDAYS(F42,G42) -> 2 | I42: =G42-F42 -> 1 | J42: =IF(X42=0,F42-1,F42+(INT(I42*X42))) -> 45993 | N42: =(G42-F42)+1 -> 2 | O42: 10 | S42: 프로그램 Source | W42: 1 | X42: 0
...

Sheet 2012 HR 배정표
A1: O HR 배정표 : 2012 | F1: ※ 매 월별, WBS 코드는 '2012 사업부문' 상에 등록된 1단 코드만 입력합니다. ※ WBS 코드를 배정한 경우, 투입률을 입력합니다. ※ 총 투입률(%)는 당월 기준으로 계산되며, 매월 해당월 열의 입력란에 색상이 표시됩니다. ※ 각 인력자원의 매월 투입률 합계는 100%(일 8시간 근무) 기준이며, +3h까지는 130%(노랑), +6h까지는 160%(주황), 그 이상은 200%(빨강)로 표시되며, 'Overtime'에 해당하므로 피로도 누적으로 생산성 저하의 원인이 됩니다.
A3: No. | B3: 자원 명 | C3: 직무능력 | D3: 투입 프로젝트 (자동 입력됨) | E3: Total | F3: 1 | H3: 2 | J3: 3 | L3: 4 | N3: 5 | P3: 6 | R3: 7 | T3: 8 | V3: 9 | X3: 10 | Z3: 11 | AB3: 12
F4: WBS코드 | G4: 투입(%) | H4: WBS코드 | I4: 투입(%) | J4: WBS코드 | K4: 투입(%) | L4: WBS코드 | M4: 투입(%) | N4: WBS코드 | O4: 투입(%) | P4: WBS코드 | Q4: 투입(%) | R4: WBS코드 | S4: 투입(%) | T4: WBS코드 | U4: 투입(%) | V4: WBS코드 | W4: 투입(%) | X4: WBS코드 | Y4: 투입(%) | Z4: WBS코드 | AA4: 투입(%) | AB4: WBS코드 | AC4: 투입(%)
A5: =IF(ISTEXT(B5)=TRUE,1,"") -> 1 | B5: 홍길동 | D5: =IF(MONTH(TODAY())<7,LEFT('Dummy(notouch)'!B2,15),LEFT('Dummy(notouch)'!C2,15)) | E5: =IF(MONTH(TODAY())=F$3,SUM(G5:G9),IF(MONTH(TODAY())=H$3,SUM(I5:I9),IF(MONTH(TODAY())=J$3,SUM(K5:K9),IF(MONTH(TODAY())=L$3,SUM(M5:M9),IF(MONTH(TODAY())=N$3,SUM(O5:O9),IF(MONTH(TODAY())=P$3,SUM(Q5:Q9),IF(MONTH(TODAY())=R$3,SUM(S5:S9),IF(MONTH(TODAY())=T$3,SUM(U5:U9),IF(MONTH(TODAY())=V$3,SUM(W5:W9),IF(MONTH(TODAY())=X$3,SUM(Y5:Y9),IF(MONTH(TODAY())=Z$3,SUM(AA5:AA9),IF(MONTH(TODAY())=AB$3,SUM(AC5:AC9))))))))))))) -> 0
D6: =IF(MONTH(TODAY())<7,LEFT('Dummy(notouch)'!B3,15),LEFT('Dummy(notouch)'!C3,15))
D7: =IF(MONTH(TODAY())<7,LEFT('Dummy(notouch)'!B4,15),LEFT('Dummy(notouch)'!C4,15))
D8: =IF(MONTH(TODAY())<7,LEFT('Dummy(notouch)'!B5,15),LEFT('Dummy(notouch)'!C5,15))
D9: =IF(MONTH(TODAY())<7,LEFT('Dummy(notouch)'!B6,15),LEFT('Dummy(notouch)'!C6,15))
A10: =IF(ISTEXT(B10)=TRUE,$A5+1,"") -> 2 | B10: 홍길순 | D10: =IF(MONTH(TODAY())<7,LEFT('Dummy(notouch)'!B7,15),LEFT('Dummy(notouch)'!C7,15)) | E10: =IF(MONTH(TODAY())=F$3,SUM(G10:G14),IF(MONTH(TODAY())=H$3,SUM(I10:I14),IF(MONTH(TODAY())=J$3,SUM(K10:K14),IF(MONTH(TODAY())=L$3,SUM(M10:M14),IF(MONTH(TODAY())=N$3,SUM(O10:O14),IF(MONTH(TODAY())=P$3,SUM(Q10:Q14),IF(MONTH(TODAY())=R$3,SUM(S10:S14),IF(MONTH(TODAY())=T$3,SUM(U10:U14),IF(MONTH(TODAY())=V$3,SUM(W10:W14),IF(MONTH(TODAY())=X$3,SUM(Y10:Y14),IF(MONTH(TODAY())=Z$3,SUM(AA10:AA14),IF(MONTH(TODAY())=AB$3,SUM(AC10:AC14))))))))))))) -> 0
D11: =IF(MONTH(TODAY())<7,LEFT('Dummy(notouch)'!B8,15),LEFT('Dummy(notouch)'!C8,15))
D12: =IF(MONTH(TODAY())<7,LEFT('Dummy(notouch)'!B9,15),LEFT('Dummy(notouch)'!C9,15))
D13: =IF(MONTH(TODAY())<7,LEFT('Dummy(notouch)'!B10,15),LEFT('Dummy(notouch)'!C10,15))
D14: =IF(MONTH(TODAY())<7,LEFT('Dummy(notouch)'!B11,15),LEFT('Dummy(notouch)'!C11,15))
A15: =IF(ISTEXT(B15)=TRUE,A10+1,"") -> 3 | B15: 홍길남 | D15: =IF(MONTH(TODAY())<7,LEFT('Dummy(notouch)'!B12,15),LEFT('Dummy(notouch)'!C12,15)) | E15: =IF(MONTH(TODAY())=F$3,SUM(G15:G19),IF(MONTH(TODAY())=H$3,SUM(I15:I19),IF(MONTH(TODAY())=J$3,SUM(K15:K19),IF(MONTH(TODAY())=L$3,SUM(M15:M19),IF(MONTH(TODAY())=N$3,SUM(O15:O19),IF(MONTH(TODAY())=P$3,SUM(Q15:Q19),IF(MONTH(TODAY())=R$3,SUM(S15:S19),IF(MONTH(TODAY())=T$3,SUM(U15:U19),IF(MONTH(TODAY())=V$3,SUM(W15:W19),IF(MONTH(TODAY())=X$3,SUM(Y15:Y19),IF(MONTH(TODAY())=Z$3,SUM(AA15:AA19),IF(MONTH(TODAY())=AB$3,SUM(AC15:AC19))))))))))))) -> 0 | L15: 2 | M15: 0.25 | N15: 2 | O15: 0.25
D16: =IF(MONTH(TODAY())<7,LEFT('Dummy(notouch)'!B13,15),LEFT('Dummy(notouch)'!C13,15))
D17: =IF(MONTH(TODAY())<7,LEFT('Dummy(notouch)'!B14,15),LEFT('Dummy(notouch)'!C14,15))
D18: =IF(MONTH(TODAY())<7,LEFT('Dummy(notouch)'!B15,15),LEFT('Dummy(notouch)'!C15,15))
D19: =IF(MONTH(TODAY())<7,LEFT('Dummy(notouch)'!B16,15),LEFT('Dummy(notouch)'!C16,15))
A20: =IF(ISTEXT(B20)=TRUE,A15+1,"") -> 4 | B20: 홍길천 | D20: =IF(MONTH(TODAY())<7,LEFT('Dummy(notouch)'!B17,15),LEFT('Dummy(notouch)'!C17,15)) | E20: =IF(MONTH(TODAY())=F$3,SUM(G20:G24),IF(MONTH(TODAY())=H$3,SUM(I20:I24),IF(MONTH(TODAY())=J$3,SUM(K20:K24),IF(MONTH(TODAY())=L$3,SUM(M20:M24),IF(MONTH(TODAY())=N$3,SUM(O20:O24),IF(MONTH(TODAY())=P$3,SUM(Q20:Q24),IF(MONTH(TODAY())=R$3,SUM(S20:S24),IF(MONTH(TODAY())=T$3,SUM(U20:U24),IF(MONTH(TODAY())=V$3,SUM(W20:W24),IF(MONTH(TODAY())=X$3,SUM(Y20:Y24),IF(MONTH(TODAY())=Z$3,SUM(AA20:AA24),IF(MONTH(TODAY())=AB$3,SUM(AC20:AC24))))))))))))) -> 0 | J20: 1
D21: =IF(MONTH(TODAY())<7,LEFT('Dummy(notouch)'!B18,15),LEFT('Dummy(notouch)'!C18,15))
D22: =IF(MONTH(TODAY())<7,LEFT('Dummy(notouch)'!B19,15),LEFT('Dummy(notouch)'!C19,15))
D23: =IF(MONTH(TODAY())<7,LEFT('Dummy(notouch)'!B20,15),LEFT('Dummy(notouch)'!C20,15))
D24: =IF(MONTH(TODAY())<7,LEFT('Dummy(notouch)'!B21,15),LEFT('Dummy(notouch)'!C21,15))
A25: =IF(ISTEXT(B25)=TRUE,A20+1,"") -> 5 | B25: 홍상두 | D25: =IF(MONTH(TODAY())<7,LEFT('Dummy(notouch)'!B22,15),LEFT('Dummy(notouch)'!C22,15)) | E25: =IF(MONTH(TODAY())=F$3,SUM(G25:G29),IF(MONTH(TODAY())=H$3,SUM(I25:I29),IF(MONTH(TODAY())=J$3,SUM(K25:K29),IF(MONTH(TODAY())=L$3,SUM(M25:M29),IF(MONTH(TODAY())=N$3,SUM(O25:O29),IF(MONTH(TODAY())=P$3,SUM(Q25:Q29),IF(MONTH(TODAY())=R$3,SUM(S25:S29),IF(MONTH(TODAY())=T$3,SUM(U25:U29),IF(MONTH(TODAY())=V$3,SUM(W25:W29),IF(MONTH(TODAY())=X$3,SUM(Y25:Y29),IF(MONTH(TODAY())=Z$3,SUM(AA25:AA29),IF(MONTH(TODAY())=AB$3,SUM(AC25:AC29))))))))))))) -> 0 | J25: 2 | K25: 1
D26: =IF(MONTH(TODAY())<7,LEFT('Dummy(notouch)'!B23,15),LEFT('Dummy(notouch)'!C23,15))
D27: =IF(MONTH(TODAY())<7,LEFT('Dummy(notouch)'!B24,15),LEFT('Dummy(notouch)'!C24,15))
D28: =IF(MONTH(TODAY())<7,LEFT('Dummy(notouch)'!B25,15),LEFT('Dummy(notouch)'!C25,15))
D29: =IF(MONTH(TODAY())<7,LEFT('Dummy(notouch)'!B26,15),LEFT('Dummy(notouch)'!C26,15))
A30: =IF(ISTEXT(B30)=TRUE,A25+1,"") -> 6 | B30: 가나다 | D30: =IF(MONTH(TODAY())<7,LEFT('Dummy(notouch)'!B27,15),LEFT('Dummy(notouch)'!C27,15)) | E30: =IF(MONTH(TODAY())=F$3,SUM(G30:G34),IF(MONTH(TODAY())=H$3,SUM(I30:I34),IF(MONTH(TODAY())=J$3,SUM(K30:K34),IF(MONTH(TODAY())=L$3,SUM(M30:M34),IF(MONTH(TODAY())=N$3,SUM(O30:O34),IF(MONTH(TODAY())=P$3,SUM(Q30:Q34),IF(MONTH(TODAY())=R$3,SUM(S30:S34),IF(MONTH(TODAY())=T$3,SUM(U30:U34),IF(MONTH(TODAY())=V$3,SUM(W30:W34),IF(MONTH(TODAY())=X$3,SUM(Y30:Y34),IF(MONTH(TODAY())=Z$3,SUM(AA30:AA34),IF(MONTH(TODAY())=AB$3,SUM(AC30:AC34))))))))))))) -> 0
D31: =IF(MONTH(TODAY())<7,LEFT('Dummy(notouch)'!B28,15),LEFT('Dummy(notouch)'!C28,15))
D32: =IF(MONTH(TODAY())<7,LEFT('Dummy(notouch)'!B29,15),LEFT('Dummy(notouch)'!C29,15))
D33: =IF(MONTH(TODAY())<7,LEFT('Dummy(notouch)'!B30,15),LEFT('Dummy(notouch)'!C30,15))
D34: =IF(MONTH(TODAY())<7,LEFT('Dummy(notouch)'!B31,15),LEFT('Dummy(notouch)'!C31,15))
A35: =IF(ISTEXT(B35)=TRUE,A30+1,"") -> 7 | B35: 라마바 | D35: =IF(MONTH(TODAY())<7,LEFT('Dummy(notouch)'!B32,15),LEFT('Dummy(notouch)'!C32,15)) | E35: =IF(MONTH(TODAY())=F$3,SUM(G35:G39),IF(MONTH(TODAY())=H$3,SUM(I35:I39),IF(MONTH(TODAY())=J$3,SUM(K35:K39),IF(MONTH(TODAY())=L$3,SUM(M35:M39),IF(MONTH(TODAY())=N$3,SUM(O35:O39),IF(MONTH(TODAY())=P$3,SUM(Q35:Q39),IF(MONTH(TODAY())=R$3,SUM(S35:S39),IF(MONTH(TODAY())=T$3,SUM(U35:U39),IF(MONTH(TODAY())=V$3,SUM(W35:W39),IF(MONTH(TODAY())=X$3,SUM(Y35:Y39),IF(MONTH(TODAY())=Z$3,SUM(AA35:AA39),IF(MONTH(TODAY())=AB$3,SUM(AC35:AC39))))))))))))) -> 0
D36: =IF(MONTH(TODAY())<7,LEFT('Dummy(notouch)'!B33,15),LEFT('Dummy(notouch)'!C33,15))
D37: =IF(MONTH(TODAY())<7,LEFT('Dummy(notouch)'!B34,15),LEFT('Dummy(notouch)'!C34,15))
D38: =IF(MONTH(TODAY())<7,LEFT('Dummy(notouch)'!B35,15),LEFT('Dummy(notouch)'!C35,15))
D39: =IF(MONTH(TODAY())<7,LEFT('Dummy(notouch)'!B36,15),LEFT('Dummy(notouch)'!C36,15))
A40: =IF(ISTEXT(B40)=TRUE,A35+1,"") -> 8 | B40: 사아자 | D40: =IF(MONTH(TODAY())<7,LEFT('Dummy(notouch)'!B37,15),LEFT('Dummy(notouch)'!C37,15)) | E40: =IF(MONTH(TODAY())=F$3,SUM(G40:G44),IF(MONTH(TODAY())=H$3,SUM(I40:I44),IF(MONTH(TODAY())=J$3,SUM(K40:K44),IF(MONTH(TODAY())=L$3,SUM(M40:M44),IF(MONTH(TODAY())=N$3,SUM(O40:O44),IF(MONTH(TODAY())=P$3,SUM(Q40:Q44),IF(MONTH(TODAY())=R$3,SUM(S40:S44),IF(MONTH(TODAY())=T$3,SUM(U40:U44),IF(MONTH(TODAY())=V$3,SUM(W40:W44),IF(MONTH(TODAY())=X$3,SUM(Y40:Y44),IF(MONTH(TODAY())=Z$3,SUM(AA40:AA44),IF(MONTH(TODAY())=AB$3,SUM(AC40:AC44))))))))))))) -> 0 | J40: 2 | K40: 0.2 | L40: 2 | M40: 0.25 | N40: 2 | O40: 0.3
D41: =IF(MONTH(TODAY())<7,LEFT('Dummy(notouch)'!B38,15),LEFT('Dummy(notouch)'!C38,15))
...

Sheet Prj_list
A1: O 프로젝트 리스트 >> 배경색이 없는 항목만 수정하시기 바랍니다.
A3: No. | B3: 프로젝트 명 | C3: Duration | E3: 투입공수 | I3: 사업관리
C4: Start | D4: End | E4: 할당 인원 | F4: 필요MM | G4: 확보MM | H4: 누락 MM | I4: 우선순위 | J4: 소요 예산 | K4: 예상 매출 | L4: 수익성
A5: 1 | B5: =IF(ISERROR(VLOOKUP($A5,WBS!$A$5:$G775,2,FALSE))=TRUE,"",IF(ISBLANK(VLOOKUP($A5,WBS!$A$5:$G775,2,FALSE))=TRUE,"",VLOOKUP($A5,WBS!$A$5:$G775,2,FALSE))) -> 전체 프로젝트 | C5: =IF(ISERROR(VLOOKUP($A5,WBS!$A5:$G775,5,FALSE))=TRUE,"",VLOOKUP($A5,WBS!$A5:$G775,5,FALSE)) -> 진행 중 | D5: =IF(ISERROR(VLOOKUP($A5,WBS!$A5:$G775,6,FALSE))=TRUE,"",VLOOKUP($A5,WBS!$A5:$G775,6,FALSE)) -> 45973 | E5: =IF(COUNTIF('2012 HR 배정표'!$G$5:$AC$400,$A5)=0,"",COUNTIF('2012 HR 배정표'!$G$5:$AC$400,$A5)) -> 11 | F5: 30 | G5: =SUMIF(Temp!$AW$7:$AW$2001,A5,Temp!$AX$7:$AX$2001) -> 4.45 | H5: =IF(F5-G5=0,"",F5-G5) -> 25.55 | I5: 2 | J5: 3000000 | K5: 2600000 | L5: =IF(ISBLANK(J5)=TRUE,"예산 입력 요망",IF(ISBLANK(K5)=TRUE,"매출 입력 요망",K5-J5)) -> -400000 | O5: 2012 | AA5: 2013
A6: 2 | B6: =IF(ISERROR(VLOOKUP($A6,WBS!$A$5:$G776,2,FALSE))=TRUE,"",IF(ISBLANK(VLOOKUP($A6,WBS!$A$5:$G776,2,FALSE))=TRUE,"",VLOOKUP($A6,WBS!$A$5:$G776,2,FALSE))) | C6: =IF(ISERROR(VLOOKUP($A6,WBS!$A6:$G776,5,FALSE))=TRUE,"",VLOOKUP($A6,WBS!$A6:$G776,5,FALSE)) | D6: =IF(ISERROR(VLOOKUP($A6,WBS!$A6:$G776,6,FALSE))=TRUE,"",VLOOKUP($A6,WBS!$A6:$G776,6,FALSE)) | E6: =IF(COUNTIF('2012 HR 배정표'!$G$5:$AC$400,$A6)=0,"",COUNTIF('2012 HR 배정표'!$G$5:$AC$400,$A6)) -> 14 | F6: 19 | G6: =SUMIF(Temp!$AW$7:$AW$2001,A6,Temp!$AX$7:$AX$2001) -> 4.95 | H6: =IF(F6-G6=0,"",F6-G6) -> 14.05 | I6: 1 | J6: 26000000 | K6: 30000000 | L6: =IF(ISBLANK(J6)=TRUE,"예산 입력 요망",IF(ISBLANK(K6)=TRUE,"매출 입력 요망",K6-J6)) -> 4000000 | N6: 월 구간 | O6: 40909 | P6: 40940 | Q6: 40969 | R6: 41000 | S6: 41030 | T6: 41061 | U6: 41091 | V6: 41122 | W6: 41153 | X6: 41183 | Y6: 41214 | Z6: 41244 | AA6: 41275 | AB6: 41306 | AC6: 41334 | AD6: 41365 | AE6: 41395 | AF6: 41426 | AG6: 41456 | AH6: 41487 | AI6: 41518 | AJ6: 41548 | AK6: 41579 | AL6: 41609
A7: 3 | B7: =IF(ISERROR(VLOOKUP($A7,WBS!$A$5:$G777,2,FALSE))=TRUE,"",IF(ISBLANK(VLOOKUP($A7,WBS!$A$5:$G777,2,FALSE))=TRUE,"",VLOOKUP($A7,WBS!$A$5:$G777,2,FALSE))) | C7: =IF(ISERROR(VLOOKUP($A7,WBS!$A6:$G777,5,FALSE))=TRUE,"",VLOOKUP($A7,WBS!$A6:$G777,5,FALSE)) | D7: =IF(ISERROR(VLOOKUP($A7,WBS!$A6:$G777,6,FALSE))=TRUE,"",VLOOKUP($A7,WBS!$A6:$G777,6,FALSE)) | E7: =IF(COUNTIF('2012 HR 배정표'!$G$5:$AC$400,$A7)=0,"",COUNTIF('2012 HR 배정표'!$G$5:$AC$400,$A7)) | G7: =SUMIF(Temp!$AW$7:$AW$2001,A7,Temp!$AX$7:$AX$2001) -> 0 | H7: =IF(F7-G7=0,"",F7-G7) | L7: =IF(ISBLANK(J7)=TRUE,"예산 입력 요망",IF(ISBLANK(K7)=TRUE,"매출 입력 요망",K7-J7)) -> 예산 입력 요망 | N7: 워킹데이 | O7: =NETWORKDAYS(O6,DATE(YEAR(O6),MONTH(O6)+1,0)) -> 22 | P7: =NETWORKDAYS(P6,DATE(YEAR(P6),MONTH(P6)+1,0)) -> 21 | Q7: =NETWORKDAYS(Q6,DATE(YEAR(Q6),MONTH(Q6)+1,0)) -> 22 | R7: =NETWORKDAYS(R6,DATE(YEAR(R6),MONTH(R6)+1,0)) -> 21 | S7: =NETWORKDAYS(S6,DATE(YEAR(S6),MONTH(S6)+1,0)) -> 23 | T7: =NETWORKDAYS(T6,DATE(YEAR(T6),MONTH(T6)+1,0)) -> 21 | U7: =NETWORKDAYS(U6,DATE(YEAR(U6),MONTH(U6)+1,0)) -> 22 | V7: =NETWORKDAYS(V6,DATE(YEAR(V6),MONTH(V6)+1,0)) -> 23 | ... AL7: =NETWORKDAYS(AL6,DATE(YEAR(AL6),MONTH(AL6)+1,0)) -> 22
A8: 4 | B8: =IF(ISERROR(VLOOKUP($A8,WBS!$A$5:$G778,2,FALSE))=TRUE,"",IF(ISBLANK(VLOOKUP($A8,WBS!$A$5:$G778,2,FALSE))=TRUE,"",VLOOKUP($A8,WBS!$A$5:$G778,2,FALSE))) | C8: =IF(ISERROR(VLOOKUP($A8,WBS!$A6:$G778,5,FALSE))=TRUE,"",VLOOKUP($A8,WBS!$A6:$G778,5,FALSE)) | D8: =IF(ISERROR(VLOOKUP($A8,WBS!$A6:$G778,6,FALSE))=TRUE,"",VLOOKUP($A8,WBS!$A6:$G778,6,FALSE)) | E8: =IF(COUNTIF('2012 HR 배정표'!$G$5:$AC$400,$A8)=0,"",COUNTIF('2012 HR 배정표'!$G$5:$AC$400,$A8)) | G8: =SUMIF(Temp!$AW$7:$AW$2001,A8,Temp!$AX$7:$AX$2001) -> 0 | H8: =IF(F8-G8=0,"",F8-G8) | L8: =IF(ISBLANK(J8)=TRUE,"예산 입력 요망",IF(ISBLANK(K8)=TRUE,"매출 입력 요망",K8-J8)) -> 예산 입력 요망
A9: 5 | B9: =IF(ISERROR(VLOOKUP($A9,WBS!$A$5:$G779,2,FALSE))=TRUE,"",IF(ISBLANK(VLOOKUP($A9,WBS!$A$5:$G779,2,FALSE))=TRUE,"",VLOOKUP($A9,WBS!$A$5:$G779,2,FALSE))) | C9: =IF(ISERROR(VLOOKUP($A9,WBS!$A6:$G779,5,FALSE))=TRUE,"",VLOOKUP($A9,WBS!$A6:$G779,5,FALSE)) | D9: =IF(ISERROR(VLOOKUP($A9,WBS!$A6:$G779,6,FALSE))=TRUE,"",VLOOKUP($A9,WBS!$A6:$G779,6,FALSE)) | E9: =IF(COUNTIF('2012 HR 배정표'!$G$5:$AC$400,$A9)=0,"",COUNTIF('2012 HR 배정표'!$G$5:$AC$400,$A9)) | G9: =SUMIF(Temp!$AW$7:$AW$2001,A9,Temp!$AX$7:$AX$2001) -> 0 | H9: =IF(F9-G9=0,"",F9-G9) | L9: =IF(ISBLANK(J9)=TRUE,"예산 입력 요망",IF(ISBLANK(K9)=TRUE,"매출 입력 요망",K9-J9)) -> 예산 입력 요망
A10: 6 | B10: =IF(ISERROR(VLOOKUP($A10,WBS!$A$5:$G780,2,FALSE))=TRUE,"",IF(ISBLANK(VLOOKUP($A10,WBS!$A$5:$G780,2,FALSE))=TRUE,"",VLOOKUP($A10,WBS!$A$5:$G780,2,FALSE))) | C10: =IF(ISERROR(VLOOKUP($A10,WBS!$A6:$G780,5,FALSE))=TRUE,"",VLOOKUP($A10,WBS!$A6:$G780,5,FALSE)) | D10: =IF(ISERROR(VLOOKUP($A10,WBS!$A6:$G780,6,FALSE))=TRUE,"",VLOOKUP($A10,WBS!$A6:$G780,6,FALSE)) | E10: =IF(COUNTIF('2012 HR 배정표'!$G$5:$AC$400,$A10)=0,"",COUNTIF('2012 HR 배정표'!$G$5:$AC$400,$A10)) | G10: =SUMIF(Temp!$AW$7:$AW$2001,A10,Temp!$AX$7:$AX$2001) -> 0 | H10: =IF(F10-G10=0,"",F10-G10) | L10: =IF(ISBLANK(J10)=TRUE,"예산 입력 요망",IF(ISBLANK(K10)=TRUE,"매출 입력 요망",K10-J10)) -> 예산 입력 요망
A11: 7 | B11: =IF(ISERROR(VLOOKUP($A11,WBS!$A$5:$G781,2,FALSE))=TRUE,"",IF(ISBLANK(VLOOKUP($A11,WBS!$A$5:$G781,2,FALSE))=TRUE,"",VLOOKUP($A11,WBS!$A$5:$G781,2,FALSE))) | C11: =IF(ISERROR(VLOOKUP($A11,WBS!$A6:$G781,5,FALSE))=TRUE,"",VLOOKUP($A11,WBS!$A6:$G781,5,FALSE)) | D11: =IF(ISERROR(VLOOKUP($A11,WBS!$A6:$G781,6,FALSE))=TRUE,"",VLOOKUP($A11,WBS!$A6:$G781,6,FALSE)) | E11: =IF(COUNTIF('2012 HR 배정표'!$G$5:$AC$400,$A11)=0,"",COUNTIF('2012 HR 배정표'!$G$5:$AC$400,$A11)) | G11: =SUMIF(Temp!$AW$7:$AW$2001,A11,Temp!$AX$7:$AX$2001) -> 0 | H11: =IF(F11-G11=0,"",F11-G11) | L11: =IF(ISBLANK(J11)=TRUE,"예산 입력 요망",IF(ISBLANK(K11)=TRUE,"매출 입력 요망",K11-J11)) -> 예산 입력 요망
A12: 8 | B12: =IF(ISERROR(VLOOKUP($A12,WBS!$A$5:$G782,2,FALSE))=TRUE,"",IF(ISBLANK(VLOOKUP($A12,WBS!$A$5:$G782,2,FALSE))=TRUE,"",VLOOKUP($A12,WBS!$A$5:$G782,2,FALSE))) | C12: =IF(ISERROR(VLOOKUP($A12,WBS!$A6:$G782,5,FALSE))=TRUE,"",VLOOKUP($A12,WBS!$A6:$G782,5,FALSE)) | D12: =IF(ISERROR(VLOOKUP($A12,WBS!$A6:$G782,6,FALSE))=TRUE,"",VLOOKUP($A12,WBS!$A6:$G782,6,FALSE)) | E12: =IF(COUNTIF('2012 HR 배정표'!$G$5:$AC$400,$A12)=0,"",COUNTIF('2012 HR 배정표'!$G$5:$AC$400,$A12)) | G12: =SUMIF(Temp!$AW$7:$AW$2001,A12,Temp!$AX$7:$AX$2001) -> 0 | H12: =IF(F12-G12=0,"",F12-G12) | L12: =IF(ISBLANK(J12)=TRUE,"예산 입력 요망",IF(ISBLANK(K12)=TRUE,"매출 입력 요망",K12-J12)) -> 예산 입력 요망
A13: 9 | B13: =IF(ISERROR(VLOOKUP($A13,WBS!$A$5:$G783,2,FALSE))=TRUE,"",IF(ISBLANK(VLOOKUP($A13,WBS!$A$5:$G783,2,FALSE))=TRUE,"",VLOOKUP($A13,WBS!$A$5:$G783,2,FALSE))) | C13: =IF(ISERROR(VLOOKUP($A13,WBS!$A6:$G783,5,FALSE))=TRUE,"",VLOOKUP($A13,WBS!$A6:$G783,5,FALSE)) | D13: =IF(ISERROR(VLOOKUP($A13,WBS!$A6:$G783,6,FALSE))=TRUE,"",VLOOKUP($A13,WBS!$A6:$G783,6,FALSE)) | E13: =IF(COUNTIF('2012 HR 배정표'!$G$5:$AC$400,$A13)=0,"",COUNTIF('2012 HR 배정표'!$G$5:$AC$400,$A13)) | G13: =SUMIF(Temp!$AW$7:$AW$2001,A13,Temp!$AX$7:$AX$2001) -> 0 | H13: =IF(F13-G13=0,"",F13-G13) | L13: =IF(ISBLANK(J13)=TRUE,"예산 입력 요망",IF(ISBLANK(K13)=TRUE,"매출 입력 요망",K13-J13)) -> 예산 입력 요망
A14: 10 | B14: =IF(ISERROR(VLOOKUP($A14,WBS!$A$5:$G784,2,FALSE))=TRUE,"",IF(ISBLANK(VLOOKUP($A14,WBS!$A$5:$G784,2,FALSE))=TRUE,"",VLOOKUP($A14,WBS!$A$5:$G784,2,FALSE))) | C14: =IF(ISERROR(VLOOKUP($A14,WBS!$A7:$G784,5,FALSE))=TRUE,"",VLOOKUP($A14,WBS!$A7:$G784,5,FALSE)) | D14: =IF(ISERROR(VLOOKUP($A14,WBS!$A7:$G784,6,FALSE))=TRUE,"",VLOOKUP($A14,WBS!$A7:$G784,6,FALSE)) | E14: =IF(COUNTIF('2012 HR 배정표'!$G$5:$AC$400,$A14)=0,"",COUNTIF('2012 HR 배정표'!$G$5:$AC$400,$A14)) | G14: =SUMIF(Temp!$AW$7:$AW$2001,A14,Temp!$AX$7:$AX$2001) -> 0 | H14: =IF(F14-G14=0,"",F14-G14) | L14: =IF(ISBLANK(J14)=TRUE,"예산 입력 요망",IF(ISBLANK(K14)=TRUE,"매출 입력 요망",K14-J14)) -> 예산 입력 요망
A15: 11 | B15: =IF(ISERROR(VLOOKUP($A15,WBS!$A$5:$G785,2,FALSE))=TRUE,"",IF(ISBLANK(VLOOKUP($A15,WBS!$A$5:$G785,2,FALSE))=TRUE,"",VLOOKUP($A15,WBS!$A$5:$G785,2,FALSE))) | C15: =IF(ISERROR(VLOOKUP($A15,WBS!$A7:$G785,5,FALSE))=TRUE,"",VLOOKUP($A15,WBS!$A7:$G785,5,FALSE)) | D15: =IF(ISERROR(VLOOKUP($A15,WBS!$A7:$G785,6,FALSE))=TRUE,"",VLOOKUP($A15,WBS!$A7:$G785,6,FALSE)) | E15: =IF(COUNTIF('2012 HR 배정표'!$G$5:$AC$400,$A15)=0,"",COUNTIF('2012 HR 배정표'!$G$5:$AC$400,$A15)) | G15: =SUMIF(Temp!$AW$7:$AW$2001,A15,Temp!$AX$7:$AX$2001) -> 0 | H15: =IF(F15-G15=0,"",F15-G15) | L15: =IF(ISBLANK(J15)=TRUE,"예산 입력 요망",IF(ISBLANK(K15)=TRUE,"매출 입력 요망",K15-J15)) -> 예산 입력 요망
A16: 12 | B16: =IF(ISERROR(VLOOKUP($A16,WBS!$A$5:$G786,2,FALSE))=TRUE,"",IF(ISBLANK(VLOOKUP($A16,WBS!$A$5:$G786,2,FALSE))=TRUE,"",VLOOKUP($A16,WBS!$A$5:$G786,2,FALSE))) | C16: =IF(ISERROR(VLOOKUP($A16,WBS!$A7:$G786,5,FALSE))=TRUE,"",VLOOKUP($A16,WBS!$A7:$G786,5,FALSE)) | D16: =IF(ISERROR(VLOOKUP($A16,WBS!$A7:$G786,6,FALSE))=TRUE,"",VLOOKUP($A16,WBS!$A7:$G786,6,FALSE)) | E16: =IF(COUNTIF('2012 HR 배정표'!$G$5:$AC$400,$A16)=0,"",COUNTIF('2012 HR 배정표'!$G$5:$AC$400,$A16)) | G16: =SUMIF(Temp!$AW$7:$AW$2001,A16,Temp!$AX$7:$AX$2001) -> 0 | H16: =IF(F16-G16=0,"",F16-G16) | L16: =IF(ISBLANK(J16)=TRUE,"예산 입력 요망",IF(ISBLANK(K16)=TRUE,"매출 입력 요망",K16-J16)) -> 예산 입력 요망
A17: 13 | B17: =IF(ISERROR(VLOOKUP($A17,WBS!$A$5:$G787,2,FALSE))=TRUE,"",IF(ISBLANK(VLOOKUP($A17,WBS!$A$5:$G787,2,FALSE))=TRUE,"",VLOOKUP($A17,WBS!$A$5:$G787,2,FALSE))) | C17: =IF(ISERROR(VLOOKUP($A17,WBS!$A10:$G787,5,FALSE))=TRUE,"",VLOOKUP($A17,WBS!$A10:$G787,5,FALSE)) | D17: =IF(ISERROR(VLOOKUP($A17,WBS!$A10:$G787,6,FALSE))=TRUE,"",VLOOKUP($A17,WBS!$A10:$G787,6,FALSE)) | E17: =IF(COUNTIF('2012 HR 배정표'!$G$5:$AC$400,$A17)=0,"",COUNTIF('2012 HR 배정표'!$G$5:$AC$400,$A17)) | G17: =SUMIF(Temp!$AW$7:$AW$2001,A17,Temp!$AX$7:$AX$2001) -> 0 | H17: =IF(F17-G17=0,"",F17-G17) | L17: =IF(ISBLANK(J17)=TRUE,"예산 입력 요망",IF(ISBLANK(K17)=TRUE,"매출 입력 요망",K17-J17)) -> 예산 입력 요망
A18: 14 | B18: =IF(ISERROR(VLOOKUP($A18,WBS!$A$5:$G788,2,FALSE))=TRUE,"",IF(ISBLANK(VLOOKUP($A18,WBS!$A$5:$G788,2,FALSE))=TRUE,"",VLOOKUP($A18,WBS!$A$5:$G788,2,FALSE))) | C18: =IF(ISERROR(VLOOKUP($A18,WBS!$A11:$G788,5,FALSE))=TRUE,"",VLOOKUP($A18,WBS!$A11:$G788,5,FALSE)) | D18: =IF(ISERROR(VLOOKUP($A18,WBS!$A11:$G788,6,FALSE))=TRUE,"",VLOOKUP($A18,WBS!$A11:$G788,6,FALSE)) | E18: =IF(COUNTIF('2012 HR 배정표'!$G$5:$AC$400,$A18)=0,"",COUNTIF('2012 HR 배정표'!$G$5:$AC$400,$A18)) | G18: =SUMIF(Temp!$AW$7:$AW$2001,A18,Temp!$AX$7:$AX$2001) -> 0 | H18: =IF(F18-G18=0,"",F18-G18) | L18: =IF(ISBLANK(J18)=TRUE,"예산 입력 요망",IF(ISBLANK(K18)=TRUE,"매출 입력 요망",K18-J18)) -> 예산 입력 요망
A19: 15 | B19: =IF(ISERROR(VLOOKUP($A19,WBS!$A$5:$G789,2,FALSE))=TRUE,"",IF(ISBLANK(VLOOKUP($A19,WBS!$A$5:$G789,2,FALSE))=TRUE,"",VLOOKUP($A19,WBS!$A$5:$G789,2,FALSE))) | C19: =IF(ISERROR(VLOOKUP($A19,WBS!$A12:$G789,5,FALSE))=TRUE,"",VLOOKUP($A19,WBS!$A12:$G789,5,FALSE)) | D19: =IF(ISERROR(VLOOKUP($A19,WBS!$A12:$G789,6,FALSE))=TRUE,"",VLOOKUP($A19,WBS!$A12:$G789,6,FALSE)) | E19: =IF(COUNTIF('2012 HR 배정표'!$G$5:$AC$400,$A19)=0,"",COUNTIF('2012 HR 배정표'!$G$5:$AC$400,$A19)) | G19: =SUMIF(Temp!$AW$7:$AW$2001,A19,Temp!$AX$7:$AX$2001) -> 0 | H19: =IF(F19-G19=0,"",F19-G19) | L19: =IF(ISBLANK(J19)=TRUE,"예산 입력 요망",IF(ISBLANK(K19)=TRUE,"매출 입력 요망",K19-J19)) -> 예산 입력 요망
A20: 16 | B20: =IF(ISERROR(VLOOKUP($A20,WBS!$A$5:$G790,2,FALSE))=TRUE,"",IF(ISBLANK(VLOOKUP($A20,WBS!$A$5:$G790,2,FALSE))=TRUE,"",VLOOKUP($A20,WBS!$A$5:$G790,2,FALSE))) | C20: =IF(ISERROR(VLOOKUP($A20,WBS!$A13:$G790,5,FALSE))=TRUE,"",VLOOKUP($A20,WBS!$A13:$G790,5,FALSE)) | D20: =IF(ISERROR(VLOOKUP($A20,WBS!$A13:$G790,6,FALSE))=TRUE,"",VLOOKUP($A20,WBS!$A13:$G790,6,FALSE)) | E20: =IF(COUNTIF('2012 HR 배정표'!$G$5:$AC$400,$A20)=0,"",COUNTIF('2012 HR 배정표'!$G$5:$AC$400,$A20)) | G20: =SUMIF(Temp!$AW$7:$AW$2001,A20,Temp!$AX$7:$AX$2001) -> 0 | H20: =IF(F20-G20=0,"",F20-G20) | L20: =IF(ISBLANK(J20)=TRUE,"예산 입력 요망",IF(ISBLANK(K20)=TRUE,"매출 입력 요망",K20-J20)) -> 예산 입력 요망
A21: 17 | B21: =IF(ISERROR(VLOOKUP($A21,WBS!$A$5:$G791,2,FALSE))=TRUE,"",IF(ISBLANK(VLOOKUP($A21,WBS!$A$5:$G791,2,FALSE))=TRUE,"",VLOOKUP($A21,WBS!$A$5:$G791,2,FALSE))) | C21: =IF(ISERROR(VLOOKUP($A21,WBS!$A16:$G791,5,FALSE))=TRUE,"",VLOOKUP($A21,WBS!$A16:$G791,5,FALSE)) | D21: =IF(ISERROR(VLOOKUP($A21,WBS!$A16:$G791,6,FALSE))=TRUE,"",VLOOKUP($A21,WBS!$A16:$G791,6,FALSE)) | E21: =IF(COUNTIF('2012 HR 배정표'!$G$5:$AC$400,$A21)=0,"",COUNTIF('2012 HR 배정표'!$G$5:$AC$400,$A21)) | G21: =SUMIF(Temp!$AW$7:$AW$2001,A21,Temp!$AX$7:$AX$2001) -> 0 | H21: =IF(F21-G21=0,"",F21-G21) | L21: =IF(ISBLANK(J21)=TRUE,"예산 입력 요망",IF(ISBLANK(K21)=TRUE,"매출 입력 요망",K21-J21)) -> 예산 입력 요망
A22: 18 | B22: =IF(ISERROR(VLOOKUP($A22,WBS!$A$5:$G792,2,FALSE))=TRUE,"",IF(ISBLANK(VLOOKUP($A22,WBS!$A$5:$G792,2,FALSE))=TRUE,"",VLOOKUP($A22,WBS!$A$5:$G792,2,FALSE))) | C22: =IF(ISERROR(VLOOKUP($A22,WBS!$A67:$G792,5,FALSE))=TRUE,"",VLOOKUP($A22,WBS!$A67:$G792,5,FALSE)) | D22: =IF(ISERROR(VLOOKUP($A22,WBS!$A67:$G792,6,FALSE))=TRUE,"",VLOOKUP($A22,WBS!$A67:$G792,6,FALSE)) | E22: =IF(COUNTIF('2012 HR 배정표'!$G$5:$AC$400,$A22)=0,"",COUNTIF('2012 HR 배정표'!$G$5:$AC$400,$A22)) | G22: =SUMIF(Temp!$AW$7:$AW$2001,A22,Temp!$AX$7:$AX$2001) -> 0 | H22: =IF(F22-G22=0,"",F22-G22) | L22: =IF(ISBLANK(J22)=TRUE,"예산 입력 요망",IF(ISBLANK(K22)=TRUE,"매출 입력 요망",K22-J22)) -> 예산 입력 요망
A23: 19 | B23: =IF(ISERROR(VLOOKUP($A23,WBS!$A$5:$G793,2,FALSE))=TRUE,"",IF(ISBLANK(VLOOKUP($A23,WBS!$A$5:$G793,2,FALSE))=TRUE,"",VLOOKUP($A23,WBS!$A$5:$G793,2,FALSE))) | C23: =IF(ISERROR(VLOOKUP($A23,WBS!$A67:$G793,5,FALSE))=TRUE,"",VLOOKUP($A23,WBS!$A67:$G793,5,FALSE)) | D23: =IF(ISERROR(VLOOKUP($A23,WBS!$A67:$G793,6,FALSE))=TRUE,"",VLOOKUP($A23,WBS!$A67:$G793,6,FALSE)) | E23: =IF(COUNTIF('2012 HR 배정표'!$G$5:$AC$400,$A23)=0,"",COUNTIF('2012 HR 배정표'!$G$5:$AC$400,$A23)) | G23: =SUMIF(Temp!$AW$7:$AW$2001,A23,Temp!$AX$7:$AX$2001) -> 0 | H23: =IF(F23-G23=0,"",F23-G23) | L23: =IF(ISBLANK(J23)=TRUE,"예산 입력 요망",IF(ISBLANK(K23)=TRUE,"매출 입력 요망",K23-J23)) -> 예산 입력 요망
A24: 20 | B24: =IF(ISERROR(VLOOKUP($A24,WBS!$A$5:$G794,2,FALSE))=TRUE,"",IF(ISBLANK(VLOOKUP($A24,WBS!$A$5:$G794,2,FALSE))=TRUE,"",VLOOKUP($A24,WBS!$A$5:$G794,2,FALSE))) | C24: =IF(ISERROR(VLOOKUP($A24,WBS!$A73:$G794,5,FALSE))=TRUE,"",VLOOKUP($A24,WBS!$A73:$G794,5,FALSE)) | D24: =IF(ISERROR(VLOOKUP($A24,WBS!$A73:$G794,6,FALSE))=TRUE,"",VLOOKUP($A24,WBS!$A73:$G794,6,FALSE)) | E24: =IF(COUNTIF('2012 HR 배정표'!$G$5:$AC$400,$A24)=0,"",COUNTIF('2012 HR 배정표'!$G$5:$AC$400,$A24)) | G24: =SUMIF(Temp!$AW$7:$AW$2001,A24,Temp!$AX$7:$AX$2001) -> 0 | H24: =IF(F24-G24=0,"",F24-G24) | L24: =IF(ISBLANK(J24)=TRUE,"예산 입력 요망",IF(ISBLANK(K24)=TRUE,"매출 입력 요망",K24-J24)) -> 예산 입력 요망
A25: 21 | B25: =IF(ISERROR(VLOOKUP($A25,WBS!$A$5:$G795,2,FALSE))=TRUE,"",IF(ISBLANK(VLOOKUP($A25,WBS!$A$5:$G795,2,FALSE))=TRUE,"",VLOOKUP($A25,WBS!$A$5:$G795,2,FALSE))) | C25: =IF(ISERROR(VLOOKUP($A25,WBS!$A73:$G795,5,FALSE))=TRUE,"",VLOOKUP($A25,WBS!$A73:$G795,5,FALSE)) | D25: =IF(ISERROR(VLOOKUP($A25,WBS!$A73:$G795,6,FALSE))=TRUE,"",VLOOKUP($A25,WBS!$A73:$G795,6,FALSE)) | E25: =IF(COUNTIF('2012 HR 배정표'!$G$5:$AC$400,$A25)=0,"",COUNTIF('2012 HR 배정표'!$G$5:$AC$400,$A25)) | G25: =SUMIF(Temp!$AW$7:$AW$2001,A25,Temp!$AX$7:$AX$2001) -> 0 | H25: =IF(F25-G25=0,"",F25-G25) | L25: =IF(ISBLANK(J25)=TRUE,"예산 입력 요망",IF(ISBLANK(K25)=TRUE,"매출 입력 요망",K25-J25)) -> 예산 입력 요망
A26: 22 | B26: =IF(ISERROR(VLOOKUP($A26,WBS!$A$5:$G796,2,FALSE))=TRUE,"",IF(ISBLANK(VLOOKUP($A26,WBS!$A$5:$G796,2,FALSE))=TRUE,"",VLOOKUP($A26,WBS!$A$5:$G796,2,FALSE))) | C26: =IF(ISERROR(VLOOKUP($A26,WBS!$A73:$G796,5,FALSE))=TRUE,"",VLOOKUP($A26,WBS!$A73:$G796,5,FALSE)) | D26: =IF(ISERROR(VLOOKUP($A26,WBS!$A73:$G796,6,FALSE))=TRUE,"",VLOOKUP($A26,WBS!$A73:$G796,6,FALSE)) | E26: =IF(COUNTIF('2012 HR 배정표'!$G$5:$AC$400,$A26)=0,"",COUNTIF('2012 HR 배정표'!$G$5:$AC$400,$A26)) | G26: =SUMIF(Temp!$AW$7:$AW$2001,A26,Temp!$AX$7:$AX$2001) -> 0 | H26: =IF(F26-G26=0,"",F26-G26) | L26: =IF(ISBLANK(J26)=TRUE,"예산 입력 요망",IF(ISBLANK(K26)=TRUE,"매출 입력 요망",K26-J26)) -> 예산 입력 요망
A27: 23 | B27: =IF(ISERROR(VLOOKUP($A27,WBS!$A$5:$G797,2,FALSE))=TRUE,"",IF(ISBLANK(VLOOKUP($A27,WBS!$A$5:$G797,2,FALSE))=TRUE,"",VLOOKUP($A27,WBS!$A$5:$G797,2,FALSE))) | C27: =IF(ISERROR(VLOOKUP($A27,WBS!$A73:$G797,5,FALSE))=TRUE,"",VLOOKUP($A27,WBS!$A73:$G797,5,FALSE)) | D27: =IF(ISERROR(VLOOKUP($A27,WBS!$A73:$G797,6,FALSE))=TRUE,"",VLOOKUP($A27,WBS!$A73:$G797,6,FALSE)) | E27: =IF(COUNTIF('2012 HR 배정표'!$G$5:$AC$400,$A27)=0,"",COUNTIF('2012 HR 배정표'!$G$5:$AC$400,$A27)) | G27: =SUMIF(Temp!$AW$7:$AW$2001,A27,Temp!$AX$7:$AX$2001) -> 0 | H27: =IF(F27-G27=0,"",F27-G27) | L27: =IF(ISBLANK(J27)=TRUE,"예산 입력 요망",IF(ISBLANK(K27)=TRUE,"매출 입력 요망",K27-J27)) -> 예산 입력 요망
A28: 24 | B28: =IF(ISERROR(VLOOKUP($A28,WBS!$A$5:$G798,2,FALSE))=TRUE,"",IF(ISBLANK(VLOOKUP($A28,WBS!$A$5:$G798,2,FALSE))=TRUE,"",VLOOKUP($A28,WBS!$A$5:$G798,2,FALSE))) | C28: =IF(ISERROR(VLOOKUP($A28,WBS!$A73:$G798,5,FALSE))=TRUE,"",VLOOKUP($A28,WBS!$A73:$G798,5,FALSE)) | D28: =IF(ISERROR(VLOOKUP($A28,WBS!$A73:$G798,6,FALSE))=TRUE,"",VLOOKUP($A28,WBS!$A73:$G798,6,FALSE)) | E28: =IF(COUNTIF('2012 HR 배정표'!$G$5:$AC$400,$A28)=0,"",COUNTIF('2012 HR 배정표'!$G$5:$AC$400,$A28)) | G28: =SUMIF(Temp!$AW$7:$AW$2001,A28,Temp!$AX$7:$AX$2001) -> 0 | H28: =IF(F28-G28=0,"",F28-G28) | L28: =IF(ISBLANK(J28)=TRUE,"예산 입력 요망",IF(ISBLANK(K28)=TRUE,"매출 입력 요망",K28-J28)) -> 예산 입력 요망
A29: 25 | B29: =IF(ISERROR(VLOOKUP($A29,WBS!$A$5:$G799,2,FALSE))=TRUE,"",IF(ISBLANK(VLOOKUP($A29,WBS!$A$5:$G799,2,FALSE))=TRUE,"",VLOOKUP($A29,WBS!$A$5:$G799,2,FALSE))) | C29: =IF(ISERROR(VLOOKUP($A29,WBS!$A73:$G799,5,FALSE))=TRUE,"",VLOOKUP($A29,WBS!$A73:$G799,5,FALSE)) | D29: =IF(ISERROR(VLOOKUP($A29,WBS!$A73:$G799,6,FALSE))=TRUE,"",VLOOKUP($A29,WBS!$A73:$G799,6,FALSE)) | E29: =IF(COUNTIF('2012 HR 배정표'!$G$5:$AC$400,$A29)=0,"",COUNTIF('2012 HR 배정표'!$G$5:$AC$400,$A29)) | G29: =SUMIF(Temp!$AW$7:$AW$2001,A29,Temp!$AX$7:$AX$2001) -> 0 | H29: =IF(F29-G29=0,"",F29-G29) | L29: =IF(ISBLANK(J29)=TRUE,"예산 입력 요망",IF(ISBLANK(K29)=TRUE,"매출 입력 요망",K29-J29)) -> 예산 입력 요망
A30: 26 | B30: =IF(ISERROR(VLOOKUP($A30,WBS!$A$5:$G800,2,FALSE))=TRUE,"",IF(ISBLANK(VLOOKUP($A30,WBS!$A$5:$G800,2,FALSE))=TRUE,"",VLOOKUP($A30,WBS!$A$5:$G800,2,FALSE))) | C30: =IF(ISERROR(VLOOKUP($A30,WBS!$A73:$G800,5,FALSE))=TRUE,"",VLOOKUP($A30,WBS!$A73:$G800,5,FALSE)) | D30: =IF(ISERROR(VLOOKUP($A30,WBS!$A73:$G800,6,FALSE))=TRUE,"",VLOOKUP($A30,WBS!$A73:$G800,6,FALSE)) | E30: =IF(COUNTIF('2012 HR 배정표'!$G$5:$AC$400,$A30)=0,"",COUNTIF('2012 HR 배정표'!$G$5:$AC$400,$A30)) | G30: =SUMIF(Temp!$AW$7:$AW$2001,A30,Temp!$AX$7:$AX$2001) -> 0 | H30: =IF(F30-G30=0,"",F30-G30) | L30: =IF(ISBLANK(J30)=TRUE,"예산 입력 요망",IF(ISBLANK(K30)=TRUE,"매출 입력 요망",K30-J30)) -> 예산 입력 요망
A31: 27 | B31: =IF(ISERROR(VLOOKUP($A31,WBS!$A$5:$G801,2,FALSE))=TRUE,"",IF(ISBLANK(VLOOKUP($A31,WBS!$A$5:$G801,2,FALSE))=TRUE,"",VLOOKUP($A31,WBS!$A$5:$G801,2,FALSE))) | C31: =IF(ISERROR(VLOOKUP($A31,WBS!$A73:$G801,5,FALSE))=TRUE,"",VLOOKUP($A31,WBS!$A73:$G801,5,FALSE)) | D31: =IF(ISERROR(VLOOKUP($A31,WBS!$A73:$G801,6,FALSE))=TRUE,"",VLOOKUP($A31,WBS!$A73:$G801,6,FALSE)) | E31: =IF(COUNTIF('2012 HR 배정표'!$G$5:$AC$400,$A31)=0,"",COUNTIF('2012 HR 배정표'!$G$5:$AC$400,$A31)) | G31: =SUMIF(Temp!$AW$7:$AW$2001,A31,Temp!$AX$7:$AX$2001) -> 0 | H31: =IF(F31-G31=0,"",F31-G31) | L31: =IF(ISBLANK(J31)=TRUE,"예산 입력 요망",IF(ISBLANK(K31)=TRUE,"매출 입력 요망",K31-J31)) -> 예산 입력 요망
A32: 28 | B32: =IF(ISERROR(VLOOKUP($A32,WBS!$A$5:$G802,2,FALSE))=TRUE,"",IF(ISBLANK(VLOOKUP($A32,WBS!$A$5:$G802,2,FALSE))=TRUE,"",VLOOKUP($A32,WBS!$A$5:$G802,2,FALSE))) | C32: =IF(ISERROR(VLOOKUP($A32,WBS!$A73:$G802,5,FALSE))=TRUE,"",VLOOKUP($A32,WBS!$A73:$G802,5,FALSE)) | D32: =IF(ISERROR(VLOOKUP($A32,WBS!$A73:$G802,6,FALSE))=TRUE,"",VLOOKUP($A32,WBS!$A73:$G802,6,FALSE)) | E32: =IF(COUNTIF('2012 HR 배정표'!$G$5:$AC$400,$A32)=0,"",COUNTIF('2012 HR 배정표'!$G$5:$AC$400,$A32)) | G32: =SUMIF(Temp!$AW$7:$AW$2001,A32,Temp!$AX$7:$AX$2001) -> 0 | H32: =IF(F32-G32=0,"",F32-G32) | L32: =IF(ISBLANK(J32)=TRUE,"예산 입력 요망",IF(ISBLANK(K32)=TRUE,"매출 입력 요망",K32-J32)) -> 예산 입력 요망
A33: 29 | B33: =IF(ISERROR(VLOOKUP($A33,WBS!$A$5:$G803,2,FALSE))=TRUE,"",IF(ISBLANK(VLOOKUP($A33,WBS!$A$5:$G803,2,FALSE))=TRUE,"",VLOOKUP($A33,WBS!$A$5:$G803,2,FALSE))) | C33: =IF(ISERROR(VLOOKUP($A33,WBS!$A73:$G803,5,FALSE))=TRUE,"",VLOOKUP($A33,WBS!$A73:$G803,5,FALSE)) | D33: =IF(ISERROR(VLOOKUP($A33,WBS!$A73:$G803,6,FALSE))=TRUE,"",VLOOKUP($A33,WBS!$A73:$G803,6,FALSE)) | E33: =IF(COUNTIF('2012 HR 배정표'!$G$5:$AC$400,$A33)=0,"",COUNTIF('2012 HR 배정표'!$G$5:$AC$400,$A33)) | G33: =SUMIF(Temp!$AW$7:$AW$2001,A33,Temp!$AX$7:$AX$2001) -> 0 | H33: =IF(F33-G33=0,"",F33-G33) | L33: =IF(ISBLANK(J33)=TRUE,"예산 입력 요망",IF(ISBLANK(K33)=TRUE,"매출 입력 요망",K33-J33)) -> 예산 입력 요망
A34: 30 | B34: =IF(ISERROR(VLOOKUP($A34,WBS!$A$5:$G804,2,FALSE))=TRUE,"",IF(ISBLANK(VLOOKUP($A34,WBS!$A$5:$G804,2,FALSE))=TRUE,"",VLOOKUP($A34,WBS!$A$5:$G804,2,FALSE))) | C34: =IF(ISERROR(VLOOKUP($A34,WBS!$A73:$G804,5,FALSE))=TRUE,"",VLOOKUP($A34,WBS!$A73:$G804,5,FALSE)) | D34: =IF(ISERROR(VLOOKUP($A34,WBS!$A73:$G804,6,FALSE))=TRUE,"",VLOOKUP($A34,WBS!$A73:$G804,6,FALSE)) | E34: =IF(COUNTIF('2012 HR 배정표'!$G$5:$AC$400,$A34)=0,"",COUNTIF('2012 HR 배정표'!$G$5:$AC$400,$A34)) | G34: =SUMIF(Temp!$AW$7:$AW$2001,A34,Temp!$AX$7:$AX$2001) -> 0 | H34: =IF(F34-G34=0,"",F34-G34) | L34: =IF(ISBLANK(J34)=TRUE,"예산 입력 요망",IF(ISBLANK(K34)=TRUE,"매출 입력 요망",K34-J34)) -> 예산 입력 요망
A35: 31 | B35: =IF(ISERROR(VLOOKUP($A35,WBS!$A$5:$G805,2,FALSE))=TRUE,"",IF(ISBLANK(VLOOKUP($A35,WBS!$A$5:$G805,2,FALSE))=TRUE,"",VLOOKUP($A35,WBS!$A$5:$G805,2,FALSE))) | C35: =IF(ISERROR(VLOOKUP($A35,WBS!$A73:$G805,5,FALSE))=TRUE,"",VLOOKUP($A35,WBS!$A73:$G805,5,FALSE)) | D35: =IF(ISERROR(VLOOKUP($A35,WBS!$A73:$G805,6,FALSE))=TRUE,"",VLOOKUP($A35,WBS!$A73:$G805,6,FALSE)) | E35: =IF(COUNTIF('2012 HR 배정표'!$G$5:$AC$400,$A35)=0,"",COUNTIF('2012 HR 배정표'!$G$5:$AC$400,$A35)) | G35: =SUMIF(Temp!$AW$7:$AW$2001,A35,Temp!$AX$7:$AX$2001) -> 0 | H35: =IF(F35-G35=0,"",F35-G35) | L35: =IF(ISBLANK(J35)=TRUE,"예산 입력 요망",IF(ISBLANK(K35)=TRUE,"매출 입력 요망",K35-J35)) -> 예산 입력 요망
A36: 32 | B36: =IF(ISERROR(VLOOKUP($A36,WBS!$A$5:$G806,2,FALSE))=TRUE,"",IF(ISBLANK(VLOOKUP($A36,WBS!$A$5:$G806,2,FALSE))=TRUE,"",VLOOKUP($A36,WBS!$A$5:$G806,2,FALSE))) | C36: =IF(ISERROR(VLOOKUP($A36,WBS!$A73:$G806,5,FALSE))=TRUE,"",VLOOKUP($A36,WBS!$A73:$G806,5,FALSE)) | D36: =IF(ISERROR(VLOOKUP($A36,WBS!$A73:$G806,6,FALSE))=TRUE,"",VLOOKUP($A36,WBS!$A73:$G806,6,FALSE)) | E36: =IF(COUNTIF('2012 HR 배정표'!$G$5:$AC$400,$A36)=0,"",COUNTIF('2012 HR 배정표'!$G$5:$AC$400,$A36)) | G36: =SUMIF(Temp!$AW$7:$AW$2001,A36,Temp!$AX$7:$AX$2001) -> 0 | H36: =IF(F36-G36=0,"",F36-G36) | L36: =IF(ISBLANK(J36)=TRUE,"예산 입력 요망",IF(ISBLANK(K36)=TRUE,"매출 입력 요망",K36-J36)) -> 예산 입력 요망
A37: 33 | B37: =IF(ISERROR(VLOOKUP($A37,WBS!$A$5:$G807,2,FALSE))=TRUE,"",IF(ISBLANK(VLOOKUP($A37,WBS!$A$5:$G807,2,FALSE))=TRUE,"",VLOOKUP($A37,WBS!$A$5:$G807,2,FALSE))) | C37: =IF(ISERROR(VLOOKUP($A37,WBS!$A73:$G807,5,FALSE))=TRUE,"",VLOOKUP($A37,WBS!$A73:$G807,5,FALSE)) | D37: =IF(ISERROR(VLOOKUP($A37,WBS!$A73:$G807,6,FALSE))=TRUE,"",VLOOKUP($A37,WBS!$A73:$G807,6,FALSE)) | E37: =IF(COUNTIF('2012 HR 배정표'!$G$5:$AC$400,$A37)=0,"",COUNTIF('2012 HR 배정표'!$G$5:$AC$400,$A37)) | G37: =SUMIF(Temp!$AW$7:$AW$2001,A37,Temp!$AX$7:$AX$2001) -> 0 | H37: =IF(F37-G37=0,"",F37-G37) | L37: =IF(ISBLANK(J37)=TRUE,"예산 입력 요망",IF(ISBLANK(K37)=TRUE,"매출 입력 요망",K37-J37)) -> 예산 입력 요망
A38: 34 | B38: =IF(ISERROR(VLOOKUP($A38,WBS!$A$5:$G808,2,FALSE))=TRUE,"",IF(ISBLANK(VLOOKUP($A38,WBS!$A$5:$G808,2,FALSE))=TRUE,"",VLOOKUP($A38,WBS!$A$5:$G808,2,FALSE))) | C38: =IF(ISERROR(VLOOKUP($A38,WBS!$A73:$G808,5,FALSE))=TRUE,"",VLOOKUP($A38,WBS!$A73:$G808,5,FALSE)) | D38: =IF(ISERROR(VLOOKUP($A38,WBS!$A73:$G808,6,FALSE))=TRUE,"",VLOOKUP($A38,WBS!$A73:$G808,6,FALSE)) | E38: =IF(COUNTIF('2012 HR 배정표'!$G$5:$AC$400,$A38)=0,"",COUNTIF('2012 HR 배정표'!$G$5:$AC$400,$A38)) | G38: =SUMIF(Temp!$AW$7:$AW$2001,A38,Temp!$AX$7:$AX$2001) -> 0 | H38: =IF(F38-G38=0,"",F38-G38) | L38: =IF(ISBLANK(J38)=TRUE,"예산 입력 요망",IF(ISBLANK(K38)=TRUE,"매출 입력 요망",K38-J38)) -> 예산 입력 요망
A39: 35 | B39: =IF(ISERROR(VLOOKUP($A39,WBS!$A$5:$G809,2,FALSE))=TRUE,"",IF(ISBLANK(VLOOKUP($A39,WBS!$A$5:$G809,2,FALSE))=TRUE,"",VLOOKUP($A39,WBS!$A$5:$G809,2,FALSE))) | C39: =IF(ISERROR(VLOOKUP($A39,WBS!$A73:$G809,5,FALSE))=TRUE,"",VLOOKUP($A39,WBS!$A73:$G809,5,FALSE)) | D39: =IF(ISERROR(VLOOKUP($A39,WBS!$A73:$G809,6,FALSE))=TRUE,"",VLOOKUP($A39,WBS!$A73:$G809,6,FALSE)) | E39: =IF(COUNTIF('2012 HR 배정표'!$G$5:$AC$400,$A39)=0,"",COUNTIF('2012 HR 배정표'!$G$5:$AC$400,$A39)) | G39: =SUMIF(Temp!$AW$7:$AW$2001,A39,Temp!$AX$7:$AX$2001) -> 0 | H39: =IF(F39-G39=0,"",F39-G39) | L39: =IF(ISBLANK(J39)=TRUE,"예산 입력 요망",IF(ISBLANK(K39)=TRUE,"매출 입력 요망",K39-J39)) -> 예산 입력 요망
A40: 36 | B40: =IF(ISERROR(VLOOKUP($A40,WBS!$A$5:$G810,2,FALSE))=TRUE,"",IF(ISBLANK(VLOOKUP($A40,WBS!$A$5:$G810,2,FALSE))=TRUE,"",VLOOKUP($A40,WBS!$A$5:$G810,2,FALSE))) | C40: =IF(ISERROR(VLOOKUP($A40,WBS!$A73:$G810,5,FALSE))=TRUE,"",VLOOKUP($A40,WBS!$A73:$G810,5,FALSE)) | D40: =IF(ISERROR(VLOOKUP($A40,WBS!$A73:$G810,6,FALSE))=TRUE,"",VLOOKUP($A40,WBS!$A73:$G810,6,FALSE)) | E40: =IF(COUNTIF('2012 HR 배정표'!$G$5:$AC$400,$A40)=0,"",COUNTIF('2012 HR 배정표'!$G$5:$AC$400,$A40)) | G40: =SUMIF(Temp!$AW$7:$AW$2001,A40,Temp!$AX$7:$AX$2001) -> 0 | H40: =IF(F40-G40=0,"",F40-G40) | L40: =IF(ISBLANK(J40)=TRUE,"예산 입력 요망",IF(ISBLANK(K40)=TRUE,"매출 입력 요망",K40-J40)) -> 예산 입력 요망
A41: 37 | B41: =IF(ISERROR(VLOOKUP($A41,WBS!$A$5:$G811,2,FALSE))=TRUE,"",IF(ISBLANK(VLOOKUP($A41,WBS!$A$5:$G811,2,FALSE))=TRUE,"",VLOOKUP($A41,WBS!$A$5:$G811,2,FALSE))) | C41: =IF(ISERROR(VLOOKUP($A41,WBS!$A73:$G811,5,FALSE))=TRUE,"",VLOOKUP($A41,WBS!$A73:$G811,5,FALSE)) | D41: =IF(ISERROR(VLOOKUP($A41,WBS!$A73:$G811,6,FALSE))=TRUE,"",VLOOKUP($A41,WBS!$A73:$G811,6,FALSE)) | E41: =IF(COUNTIF('2012 HR 배정표'!$G$5:$AC$400,$A41)=0,"",COUNTIF('2012 HR 배정표'!$G$5:$AC$400,$A41)) | G41: =SUMIF(Temp!$AW$7:$AW$2001,A41,Temp!$AX$7:$AX$2001) -> 0 | H41: =IF(F41-G41=0,"",F41-G41) | L41: =IF(ISBLANK(J41)=TRUE,"예산 입력 요망",IF(ISBLANK(K41)=TRUE,"매출 입력 요망",K41-J41)) -> 예산 입력 요망
...

Sheet Dummy(notouch)
B1: Dumy 수식 >>> 본 장표의 B,C열을 입력/수정/삭제하지 마세요.
B2: =IF(AND(MONTH(TODAY())='2012 HR 배정표'!F$3,ISNUMBER('2012 HR 배정표'!F5)=TRUE),VLOOKUP('2012 HR 배정표'!F5,Prj_list!$A$5:$B$201,2,FALSE),IF(AND(MONTH(TODAY())='2012 HR 배정표'!H$3,ISNUMBER('2012 HR 배정표'!H5)=TRUE),VLOOKUP('2012 HR 배정표'!H5,Prj_list!$A$5:$B$201,2,FALSE),IF(AND(MONTH(TODAY())='2012 HR 배정표'!J$3,ISNUMBER('2012 HR 배정표'!J5)=TRUE),VLOOKUP('2012 HR 배정표'!J5,Prj_list!$A$5:$B$201,2,FALSE),IF(AND(MONTH(TODAY())='2012 HR 배정표'!L$3,ISNUMBER('2012 HR 배정표'!L5)=TRUE),VLOOKUP('2012 HR 배정표'!L5,Prj_list!$A$5:$B$201,2,FALSE),IF(AND(MONTH(TODAY())='2012 HR 배정표'!N$3,ISNUMBER('2012 HR 배정표'!N5)=TRUE),VLOOKUP('2012 HR 배정표'!N5,Prj_list!$A$5:$B$201,2,FALSE),""))))) | C2: =IF(AND(MONTH(TODAY())='2012 HR 배정표'!P$3,ISNUMBER('2012 HR 배정표'!P5)=TRUE),VLOOKUP('2012 HR 배정표'!P5,Prj_list!$A$5:$B$201,2,FALSE),IF(AND(MONTH(TODAY())='2012 HR 배정표'!R$3,ISNUMBER('2012 HR 배정표'!R5)=TRUE),VLOOKUP('2012 HR 배정표'!R5,Prj_list!$A$5:$B$201,2,FALSE),IF(AND(MONTH(TODAY())='2012 HR 배정표'!T$3,ISNUMBER('2012 HR 배정표'!T5)=TRUE),VLOOKUP('2012 HR 배정표'!T5,Prj_list!$A$5:$B$201,2,FALSE),IF(AND(MONTH(TODAY())='2012 HR 배정표'!V$3,ISNUMBER('2012 HR 배정표'!V5)=TRUE),VLOOKUP('2012 HR 배정표'!V5,Prj_list!$A$5:$B$201,2,FALSE),IF(AND(MONTH(TODAY())='2012 HR 배정표'!X$3,ISNUMBER('2012 HR 배정표'!X5)=TRUE),VLOOKUP('2012 HR 배정표'!X5,Prj_list!$A$5:$B$201,2,FALSE),IF(AND(MONTH(TODAY())='2012 HR 배정표'!Z$3,ISNUMBER('2012 HR 배정표'!Z5)=TRUE),VLOOKUP('2012 HR 배정표'!Z5,Prj_list!$A$5:$B$201,2,FALSE),IF(AND(MONTH(TODAY())='2012 HR 배정표'!AB$3,ISNUMBER('2012 HR 배정표'!AB5)=TRUE),VLOOKUP('2012 HR 배정표'!AB5,Prj_list!$A$5:$B$201,2,FALSE),"")))))))
B3: =IF(AND(MONTH(TODAY())='2012 HR 배정표'!F$3,ISNUMBER('2012 HR 배정표'!F6)=TRUE),VLOOKUP('2012 HR 배정표'!F6,Prj_list!$A$5:$B$201,2,FALSE),IF(AND(MONTH(TODAY())='2012 HR 배정표'!H$3,ISNUMBER('2012 HR 배정표'!H6)=TRUE),VLOOKUP('2012 HR 배정표'!H6,Prj_list!$A$5:$B$201,2,FALSE),IF(AND(MONTH(TODAY())='2012 HR 배정표'!J$3,ISNUMBER('2012 HR 배정표'!J6)=TRUE),VLOOKUP('2012 HR 배정표'!J6,Prj_list!$A$5:$B$201,2,FALSE),IF(AND(MONTH(TODAY())='2012 HR 배정표'!L$3,ISNUMBER('2012 HR 배정표'!L6)=TRUE),VLOOKUP('2012 HR 배정표'!L6,Prj_list!$A$5:$B$201,2,FALSE),IF(AND(MONTH(TODAY())='2012 HR 배정표'!N$3,ISNUMBER('2012 HR 배정표'!N6)=TRUE),VLOOKUP('2012 HR 배정표'!N6,Prj_list!$A$5:$B$201,2,FALSE),""))))) | C3: =IF(AND(MONTH(TODAY())='2012 HR 배정표'!P$3,ISNUMBER('2012 HR 배정표'!P6)=TRUE),VLOOKUP('2012 HR 배정표'!P6,Prj_list!$A$5:$B$201,2,FALSE),IF(AND(MONTH(TODAY())='2012 HR 배정표'!R$3,ISNUMBER('2012 HR 배정표'!R6)=TRUE),VLOOKUP('2012 HR 배정표'!R6,Prj_list!$A$5:$B$201,2,FALSE),IF(AND(MONTH(TODAY())='2012 HR 배정표'!T$3,ISNUMBER('2012 HR 배정표'!T6)=TRUE),VLOOKUP('2012 HR 배정표'!T6,Prj_list!$A$5:$B$201,2,FALSE),IF(AND(MONTH(TODAY())='2012 HR 배정표'!V$3,ISNUMBER('2012 HR 배정표'!V6)=TRUE),VLOOKUP('2012 HR 배정표'!V6,Prj_list!$A$5:$B$201,2,FALSE),IF(AND(MONTH(TODAY())='2012 HR 배정표'!X$3,ISNUMBER('2012 HR 배정표'!X6)=TRUE),VLOOKUP('2012 HR 배정표'!X6,Prj_list!$A$5:$B$201,2,FALSE),IF(AND(MONTH(TODAY())='2012 HR 배정표'!Z$3,ISNUMBER('2012 HR 배정표'!Z6)=TRUE),VLOOKUP('2012 HR 배정표'!Z6,Prj_list!$A$5:$B$201,2,FALSE),IF(AND(MONTH(TODAY())='2012 HR 배정표'!AB$3,ISNUMBER('2012 HR 배정표'!AB6)=TRUE),VLOOKUP('2012 HR 배정표'!AB6,Prj_list!$A$5:$B$201,2,FALSE),"")))))))
B4: =IF(AND(MONTH(TODAY())='2012 HR 배정표'!F$3,ISNUMBER('2012 HR 배정표'!F7)=TRUE),VLOOKUP('2012 HR 배정표'!F7,Prj_list!$A$5:$B$201,2,FALSE),IF(AND(MONTH(TODAY())='2012 HR 배정표'!H$3,ISNUMBER('2012 HR 배정표'!H7)=TRUE),VLOOKUP('2012 HR 배정표'!H7,Prj_list!$A$5:$B$201,2,FALSE),IF(AND(MONTH(TODAY())='2012 HR 배정표'!J$3,ISNUMBER('2012 HR 배정표'!J7)=TRUE),VLOOKUP('2012 HR 배정표'!J7,Prj_list!$A$5:$B$201,2,FALSE),IF(AND(MONTH(TODAY())='2012 HR 배정표'!L$3,ISNUMBER('2012 HR 배정표'!L7)=TRUE),VLOOKUP('2012 HR 배정표'!L7,Prj_list!$A$5:$B$201,2,FALSE),IF(AND(MONTH(TODAY())='2012 HR 배정표'!N$3,ISNUMBER('2012 HR 배정표'!N7)=TRUE),VLOOKUP('2012 HR 배정표'!N7,Prj_list!$A$5:$B$201,2,FALSE),""))))) | C4: =IF(AND(MONTH(TODAY())='2012 HR 배정표'!P$3,ISNUMBER('2012 HR 배정표'!P7)=TRUE),VLOOKUP('2012 HR 배정표'!P7,Prj_list!$A$5:$B$201,2,FALSE),IF(AND(MONTH(TODAY())='2012 HR 배정표'!R$3,ISNUMBER('2012 HR 배정표'!R7)=TRUE),VLOOKUP('2012 HR 배정표'!R7,Prj_list!$A$5:$B$201,2,FALSE),IF(AND(MONTH(TODAY())='2012 HR 배정표'!T$3,ISNUMBER('2012 HR 배정표'!T7)=TRUE),VLOOKUP('2012 HR 배정표'!T7,Prj_list!$A$5:$B$201,2,FALSE),IF(AND(MONTH(TODAY())='2012 HR 배정표'!V$3,ISNUMBER('2012 HR 배정표'!V7)=TRUE),VLOOKUP('2012 HR 배정표'!V7,Prj_list!$A$5:$B$201,2,FALSE),IF(AND(MONTH(TODAY())='2012 HR 배정표'!X$3,ISNUMBER('2012 HR 배정표'!X7)=TRUE),VLOOKUP('2012 HR 배정표'!X7,Prj_list!$A$5:$B$201,2,FALSE),IF(AND(MONTH(TODAY())='2012 HR 배정표'!Z$3,ISNUMBER('2012 HR 배정표'!Z7)=TRUE),VLOOKUP('2012 HR 배정표'!Z7,Prj_list!$A$5:$B$201,2,FALSE),IF(AND(MONTH(TODAY())='2012 HR 배정표'!AB$3,ISNUMBER('2012 HR 배정표'!AB7)=TRUE),VLOOKUP('2012 HR 배정표'!AB7,Prj_list!$A$5:$B$201,2,FALSE),"")))))))
B5: =IF(AND(MONTH(TODAY())='2012 HR 배정표'!F$3,ISNUMBER('2012 HR 배정표'!F8)=TRUE),VLOOKUP('2012 HR 배정표'!F8,Prj_list!$A$5:$B$201,2,FALSE),IF(AND(MONTH(TODAY())='2012 HR 배정표'!H$3,ISNUMBER('2012 HR 배정표'!H8)=TRUE),VLOOKUP('2012 HR 배정표'!H8,Prj_list!$A$5:$B$201,2,FALSE),IF(AND(MONTH(TODAY())='2012 HR 배정표'!J$3,ISNUMBER('2012 HR 배정표'!J8)=TRUE),VLOOKUP('2012 HR 배정표'!J8,Prj_list!$A$5:$B$201,2,FALSE),IF(AND(MONTH(TODAY())='2012 HR 배정표'!L$3,ISNUMBER('2012 HR 배정표'!L8)=TRUE),VLOOKUP('2012 HR 배정표'!L8,Prj_list!$A$5:$B$201,2,FALSE),IF(AND(MONTH(TODAY())='2012 HR 배정표'!N$3,ISNUMBER('2012 HR 배정표'!N8)=TRUE),VLOOKUP('2012 HR 배정표'!N8,Prj_list!$A$5:$B$201,2,FALSE),""))))) | C5: =IF(AND(MONTH(TODAY())='2012 HR 배정표'!P$3,ISNUMBER('2012 HR 배정표'!P8)=TRUE),VLOOKUP('2012 HR 배정표'!P8,Prj_list!$A$5:$B$201,2,FALSE),IF(AND(MONTH(TODAY())='2012 HR 배정표'!R$3,ISNUMBER('2012 HR 배정표'!R8)=TRUE),VLOOKUP('2012 HR 배정표'!R8,Prj_list!$A$5:$B$201,2,FALSE),IF(AND(MONTH(TODAY())='2012 HR 배정표'!T$3,ISNUMBER('2012 HR 배정표'!T8)=TRUE),VLOOKUP('2012 HR 배정표'!T8,Prj_list!$A$5:$B$201,2,FALSE),IF(AND(MONTH(TODAY())='2012 HR 배정표'!V$3,ISNUMBER('2012 HR 배정표'!V8)=TRUE),VLOOKUP('2012 HR 배정표'!V8,Prj_list!$A$5:$B$201,2,FALSE),IF(AND(MONTH(TODAY())='2012 HR 배정표'!X$3,ISNUMBER('2012 HR 배정표'!X8)=TRUE),VLOOKUP('2012 HR 배정표'!X8,Prj_list!$A$5:$B$201,2,FALSE),IF(AND(MONTH(TODAY())='2012 HR 배정표'!Z$3,ISNUMBER('2012 HR 배정표'!Z8)=TRUE),VLOOKUP('2012 HR 배정표'!Z8,Prj_list!$A$5:$B$201,2,FALSE),IF(AND(MONTH(TODAY())='2012 HR 배정표'!AB$3,ISNUMBER('2012 HR 배정표'!AB8)=TRUE),VLOOKUP('2012 HR 배정표'!AB8,Prj_list!$A$5:$B$201,2,FALSE),"")))))))
B6: =IF(AND(MONTH(TODAY())='2012 HR 배정표'!F$3,ISNUMBER('2012 HR 배정표'!F9)=TRUE),VLOOKUP('2012 HR 배정표'!F9,Prj_list!$A$5:$B$201,2,FALSE),IF(AND(MONTH(TODAY())='2012 HR 배정표'!H$3,ISNUMBER('2012 HR 배정표'!H9)=TRUE),VLOOKUP('2012 HR 배정표'!H9,Prj_list!$A$5:$B$201,2,FALSE),IF(AND(MONTH(TODAY())='2012 HR 배정표'!J$3,ISNUMBER('2012 HR 배정표'!J9)=TRUE),VLOOKUP('2012 HR 배정표'!J9,Prj_list!$A$5:$B$201,2,FALSE),IF(AND(MONTH(TODAY())='2012 HR 배정표'!L$3,ISNUMBER('2012 HR 배정표'!L9)=TRUE),VLOOKUP('2012 HR 배정표'!L9,Prj_list!$A$5:$B$201,2,FALSE),IF(AND(MONTH(TODAY())='2012 HR 배정표'!N$3,ISNUMBER('2012 HR 배정표'!N9)=TRUE),VLOOKUP('2012 HR 배정표'!N9,Prj_list!$A$5:$B$201,2,FALSE),""))))) | C6: =IF(AND(MONTH(TODAY())='2012 HR 배정표'!P$3,ISNUMBER('2012 HR 배정표'!P9)=TRUE),VLOOKUP('2012 HR 배정표'!P9,Prj_list!$A$5:$B$201,2,FALSE),IF(AND(MONTH(TODAY())='2012 HR 배정표'!R$3,ISNUMBER('2012 HR 배정표'!R9)=TRUE),VLOOKUP('2012 HR 배정표'!R9,Prj_list!$A$5:$B$201,2,FALSE),IF(AND(MONTH(TODAY())='2012 HR 배정표'!T$3,ISNUMBER('2012 HR 배정표'!T9)=TRUE),VLOOKUP('2012 HR 배정표'!T9,Prj_list!$A$5:$B$201,2,FALSE),IF(AND(MONTH(TODAY())='2012 HR 배정표'!V$3,ISNUMBER('2012 HR 배정표'!V9)=TRUE),VLOOKUP('2012 HR 배정표'!V9,Prj_list!$A$5:$B$201,2,FALSE),IF(AND(MONTH(TODAY())='2012 HR 배정표'!X$3,ISNUMBER('2012 HR 배정표'!X9)=TRUE),VLOOKUP('2012 HR 배정표'!X9,Prj_list!$A$5:$B$201,2,FALSE),IF(AND(MONTH(TODAY())='2012 HR 배정표'!Z$3,ISNUMBER('2012 HR 배정표'!Z9)=TRUE),VLOOKUP('2012 HR 배정표'!Z9,Prj_list!$A$5:$B$201,2,FALSE),IF(AND(MONTH(TODAY())='2012 HR 배정표'!AB$3,ISNUMBER('2012 HR 배정표'!AB9)=TRUE),VLOOKUP('2012 HR 배정표'!AB9,Prj_list!$A$5:$B$201,2,FALSE),"")))))))
B7: =IF(AND(MONTH(TODAY())='2012 HR 배정표'!F$3,ISNUMBER('2012 HR 배정표'!F10)=TRUE),VLOOKUP('2012 HR 배정표'!F10,Prj_list!$A$5:$B$201,2,FALSE),IF(AND(MONTH(TODAY())='2012 HR 배정표'!H$3,ISNUMBER('2012 HR 배정표'!H10)=TRUE),VLOOKUP('2012 HR 배정표'!H10,Prj_list!$A$5:$B$201,2,FALSE),IF(AND(MONTH(TODAY())='2012 HR 배정표'!J$3,ISNUMBER('2012 HR 배정표'!J10)=TRUE),VLOOKUP('2012 HR 배정표'!J10,Prj_list!$A$5:$B$201,2,FALSE),IF(AND(MONTH(TODAY())='2012 HR 배정표'!L$3,ISNUMBER('2012 HR 배정표'!L10)=TRUE),VLOOKUP('2012 HR 배정표'!L10,Prj_list!$A$5:$B$201,2,FALSE),IF(AND(MONTH(TODAY())='2012 HR 배정표'!N$3,ISNUMBER('2012 HR 배정표'!N10)=TRUE),VLOOKUP('2012 HR 배정표'!N10,Prj_list!$A$5:$B$201,2,FALSE),""))))) | C7: =IF(AND(MONTH(TODAY())='2012 HR 배정표'!P$3,ISNUMBER('2012 HR 배정표'!P10)=TRUE),VLOOKUP('2012 HR 배정표'!P10,Prj_list!$A$5:$B$201,2,FALSE),IF(AND(MONTH(TODAY())='2012 HR 배정표'!R$3,ISNUMBER('2012 HR 배정표'!R10)=TRUE),VLOOKUP('2012 HR 배정표'!R10,Prj_list!$A$5:$B$201,2,FALSE),IF(AND(MONTH(TODAY())='2012 HR 배정표'!T$3,ISNUMBER('2012 HR 배정표'!T10)=TRUE),VLOOKUP('2012 HR 배정표'!T10,Prj_list!$A$5:$B$201,2,FALSE),IF(AND(MONTH(TODAY())='2012 HR 배정표'!V$3,ISNUMBER('2012 HR 배정표'!V10)=TRUE),VLOOKUP('2012 HR 배정표'!V10,Prj_list!$A$5:$B$201,2,FALSE),IF(AND(MONTH(TODAY())='2012 HR 배정표'!X$3,ISNUMBER('2012 HR 배정표'!X10)=TRUE),VLOOKUP('2012 HR 배정표'!X10,Prj_list!$A$5:$B$201,2,FALSE),IF(AND(MONTH(TODAY())='2012 HR 배정표'!Z$3,ISNUMBER('2012 HR 배정표'!Z10)=TRUE),VLOOKUP('2012 HR 배정표'!Z10,Prj_list!$A$5:$B$201,2,FALSE),IF(AND(MONTH(TODAY())='2012 HR 배정표'!AB$3,ISNUMBER('2012 HR 배정표'!AB10)=TRUE),VLOOKUP('2012 HR 배정표'!AB10,Prj_list!$A$5:$B$201,2,FALSE),"")))))))
B8: =IF(AND(MONTH(TODAY())='2012 HR 배정표'!F$3,ISNUMBER('2012 HR 배정표'!F11)=TRUE),VLOOKUP('2012 HR 배정표'!F11,Prj_list!$A$5:$B$201,2,FALSE),IF(AND(MONTH(TODAY())='2012 HR 배정표'!H$3,ISNUMBER('2012 HR 배정표'!H11)=TRUE),VLOOKUP('2012 HR 배정표'!H11,Prj_list!$A$5:$B$201,2,FALSE),IF(AND(MONTH(TODAY())='2012 HR 배정표'!J$3,ISNUMBER('2012 HR 배정표'!J11)=TRUE),VLOOKUP('2012 HR 배정표'!J11,Prj_list!$A$5:$B$201,2,FALSE),IF(AND(MONTH(TODAY())='2012 HR 배정표'!L$3,ISNUMBER('2012 HR 배정표'!L11)=TRUE),VLOOKUP('2012 HR 배정표'!L11,Prj_list!$A$5:$B$201,2,FALSE),IF(AND(MONTH(TODAY())='2012 HR 배정표'!N$3,ISNUMBER('2012 HR 배정표'!N11)=TRUE),VLOOKUP('2012 HR 배정표'!N11,Prj_list!$A$5:$B$201,2,FALSE),""))))) | C8: =IF(AND(MONTH(TODAY())='2012 HR 배정표'!P$3,ISNUMBER('2012 HR 배정표'!P11)=TRUE),VLOOKUP('2012 HR 배정표'!P11,Prj_list!$A$5:$B$201,2,FALSE),IF(AND(MONTH(TODAY())='2012 HR 배정표'!R$3,ISNUMBER('2012 HR 배정표'!R11)=TRUE),VLOOKUP('2012 HR 배정표'!R11,Prj_list!$A$5:$B$201,2,FALSE),IF(AND(MONTH(TODAY())='2012 HR 배정표'!T$3,ISNUMBER('2012 HR 배정표'!T11)=TRUE),VLOOKUP('2012 HR 배정표'!T11,Prj_list!$A$5:$B$201,2,FALSE),IF(AND(MONTH(TODAY())='2012 HR 배정표'!V$3,ISNUMBER('2012 HR 배정표'!V11)=TRUE),VLOOKUP('2012 HR 배정표'!V11,Prj_list!$A$5:$B$201,2,FALSE),IF(AND(MONTH(TODAY())='2012 HR 배정표'!X$3,ISNUMBER('2012 HR 배정표'!X11)=TRUE),VLOOKUP('2012 HR 배정표'!X11,Prj_list!$A$5:$B$201,2,FALSE),IF(AND(MONTH(TODAY())='2012 HR 배정표'!Z$3,ISNUMBER('2012 HR 배정표'!Z11)=TRUE),VLOOKUP('2012 HR 배정표'!Z11,Prj_list!$A$5:$B$201,2,FALSE),IF(AND(MONTH(TODAY())='2012 HR 배정표'!AB$3,ISNUMBER('2012 HR 배정표'!AB11)=TRUE),VLOOKUP('2012 HR 배정표'!AB11,Prj_list!$A$5:$B$201,2,FALSE),"")))))))
B9: =IF(AND(MONTH(TODAY())='2012 HR 배정표'!F$3,ISNUMBER('2012 HR 배정표'!F12)=TRUE),VLOOKUP('2012 HR 배정표'!F12,Prj_list!$A$5:$B$201,2,FALSE),IF(AND(MONTH(TODAY())='2012 HR 배정표'!H$3,ISNUMBER('2012 HR 배정표'!H12)=TRUE),VLOOKUP('2012 HR 배정표'!H12,Prj_list!$A$5:$B$201,2,FALSE),IF(AND(MONTH(TODAY())='2012 HR 배정표'!J$3,ISNUMBER('2012 HR 배정표'!J12)=TRUE),VLOOKUP('2012 HR 배정표'!J12,Prj_list!$A$5:$B$201,2,FALSE),IF(AND(MONTH(TODAY())='2012 HR 배정표'!L$3,ISNUMBER('2012 HR 배정표'!L12)=TRUE),VLOOKUP('2012 HR 배정표'!L12,Prj_list!$A$5:$B$201,2,FALSE),IF(AND(MONTH(TODAY())='2012 HR 배정표'!N$3,ISNUMBER('2012 HR 배정표'!N12)=TRUE),VLOOKUP('2012 HR 배정표'!N12,Prj_list!$A$5:$B$201,2,FALSE),""))))) | C9: =IF(AND(MONTH(TODAY())='2012 HR 배정표'!P$3,ISNUMBER('2012 HR 배정표'!P12)=TRUE),VLOOKUP('2012 HR 배정표'!P12,Prj_list!$A$5:$B$201,2,FALSE),IF(AND(MONTH(TODAY())='2012 HR 배정표'!R$3,ISNUMBER('2012 HR 배정표'!R12)=TRUE),VLOOKUP('2012 HR 배정표'!R12,Prj_list!$A$5:$B$201,2,FALSE),IF(AND(MONTH(TODAY())='2012 HR 배정표'!T$3,ISNUMBER('2012 HR 배정표'!T12)=TRUE),VLOOKUP('2012 HR 배정표'!T12,Prj_list!$A$5:$B$201,2,FALSE),IF(AND(MONTH(TODAY())='2012 HR 배정표'!V$3,ISNUMBER('2012 HR 배정표'!V12)=TRUE),VLOOKUP('2012 HR 배정표'!V12,Prj_list!$A$5:$B$201,2,FALSE),IF(AND(MONTH(TODAY())='2012 HR 배정표'!X$3,ISNUMBER('2012 HR 배정표'!X12)=TRUE),VLOOKUP('2012 HR 배정표'!X12,Prj_list!$A$5:$B$201,2,FALSE),IF(AND(MONTH(TODAY())='2012 HR 배정표'!Z$3,ISNUMBER('2012 HR 배정표'!Z12)=TRUE),VLOOKUP('2012 HR 배정표'!Z12,Prj_list!$A$5:$B$201,2,FALSE),IF(AND(MONTH(TODAY())='2012 HR 배정표'!AB$3,ISNUMBER('2012 HR 배정표'!AB12)=TRUE),VLOOKUP('2012 HR 배정표'!AB12,Prj_list!$A$5:$B$201,2,FALSE),"")))))))
B10: =IF(AND(MONTH(TODAY())='2012 HR 배정표'!F$3,ISNUMBER('2012 HR 배정표'!F13)=TRUE),VLOOKUP('2012 HR 배정표'!F13,Prj_list!$A$5:$B$201,2,FALSE),IF(AND(MONTH(TODAY())='2012 HR 배정표'!H$3,ISNUMBER('2012 HR 배정표'!H13)=TRUE),VLOOKUP('2012 HR 배정표'!H13,Prj_list!$A$5:$B$201,2,FALSE),IF(AND(MONTH(TODAY())='2012 HR 배정표'!J$3,ISNUMBER('2012 HR 배정표'!J13)=TRUE),VLOOKUP('2012 HR 배정표'!J13,Prj_list!$A$5:$B$201,2,FALSE),IF(AND(MONTH(TODAY())='2012 HR 배정표'!L$3,ISNUMBER('2012 HR 배정표'!L13)=TRUE),VLOOKUP('2012 HR 배정표'!L13,Prj_list!$A$5:$B$201,2,FALSE),IF(AND(MONTH(TODAY())='2012 HR 배정표'!N$3,ISNUMBER('2012 HR 배정표'!N13)=TRUE),VLOOKUP('2012 HR 배정표'!N13,Prj_list!$A$5:$B$201,2,FALSE),""))))) | C10: =IF(AND(MONTH(TODAY())='2012 HR 배정표'!P$3,ISNUMBER('2012 HR 배정표'!P13)=TRUE),VLOOKUP('2012 HR 배정표'!P13,Prj_list!$A$5:$B$201,2,FALSE),IF(AND(MONTH(TODAY())='2012 HR 배정표'!R$3,ISNUMBER('2012 HR 배정표'!R13)=TRUE),VLOOKUP('2012 HR 배정표'!R13,Prj_list!$A$5:$B$201,2,FALSE),IF(AND(MONTH(TODAY())='2012 HR 배정표'!T$3,ISNUMBER('2012 HR 배정표'!T13)=TRUE),VLOOKUP('2012 HR 배정표'!T13,Prj_list!$A$5:$B$201,2,FALSE),IF(AND(MONTH(TODAY())='2012 HR 배정표'!V$3,ISNUMBER('2012 HR 배정표'!V13)=TRUE),VLOOKUP('2012 HR 배정표'!V13,Prj_list!$A$5:$B$201,2,FALSE),IF(AND(MONTH(TODAY())='2012 HR 배정표'!X$3,ISNUMBER('2012 HR 배정표'!X13)=TRUE),VLOOKUP('2012 HR 배정표'!X13,Prj_list!$A$5:$B$201,2,FALSE),IF(AND(MONTH(TODAY())='2012 HR 배정표'!Z$3,ISNUMBER('2012 HR 배정표'!Z13)=TRUE),VLOOKUP('2012 HR 배정표'!Z13,Prj_list!$A$5:$B$201,2,FALSE),IF(AND(MONTH(TODAY())='2012 HR 배정표'!AB$3,ISNUMBER('2012 HR 배정표'!AB13)=TRUE),VLOOKUP('2012 HR 배정표'!AB13,Prj_list!$A$5:$B$201,2,FALSE),"")))))))
